INFO 2021-06-10 00:16:39,201 autoreload 636 Watching for file changes with StatReloader
INFO 2021-06-10 00:16:55,905 autoreload 636 Watching for file changes with StatReloader
INFO 2021-06-10 00:31:56,446 autoreload 636 Watching for file changes with StatReloader
INFO 2021-06-10 00:33:05,440 autoreload 636 Watching for file changes with StatReloader
INFO 2021-06-10 00:34:29,321 autoreload 250 F:\Python\Python_Project\python_test_developer\main\settings.py changed, reloading.
INFO 2021-06-10 00:34:31,698 autoreload 636 Watching for file changes with StatReloader
INFO 2021-06-10 00:35:15,133 autoreload 636 Watching for file changes with StatReloader
INFO 2021-06-10 00:36:18,026 autoreload 636 Watching for file changes with StatReloader
INFO 2021-06-10 00:36:33,051 autoreload 636 Watching for file changes with StatReloader
INFO 2021-06-10 00:36:54,569 autoreload 636 Watching for file changes with StatReloader
INFO 2021-06-10 00:37:18,731 autoreload 636 Watching for file changes with StatReloader
INFO 2021-06-10 00:37:41,318 autoreload 636 Watching for file changes with StatReloader
INFO 2021-06-10 00:38:04,099 autoreload 636 Watching for file changes with StatReloader
INFO 2021-06-10 00:40:57,905 autoreload 636 Watching for file changes with StatReloader
INFO 2021-06-10 00:43:28,570 autoreload 636 Watching for file changes with StatReloader
WARNING 2021-06-10 00:43:35,184 log 224 Forbidden: /interfaces/
WARNING 2021-06-10 00:43:35,186 basehttp 161 "POST /interfaces/ HTTP/1.1" 403 43
WARNING 2021-06-10 00:43:49,071 log 224 Not Found: /
WARNING 2021-06-10 00:43:49,073 basehttp 161 "GET / HTTP/1.1" 404 2381
WARNING 2021-06-10 00:43:49,203 log 224 Not Found: /favicon.ico
WARNING 2021-06-10 00:43:49,205 basehttp 161 "GET /favicon.ico HTTP/1.1" 404 2432
WARNING 2021-06-10 00:43:59,937 log 224 Forbidden: /interfaces/
WARNING 2021-06-10 00:43:59,939 basehttp 161 "GET /interfaces/ HTTP/1.1" 403 5045
INFO 2021-06-10 00:43:59,988 basehttp 161 "GET /static/rest_framework/css/bootstrap.min.css HTTP/1.1" 304 0
INFO 2021-06-10 00:43:59,995 basehttp 161 "GET /static/rest_framework/css/bootstrap-tweaks.css HTTP/1.1" 304 0
INFO 2021-06-10 00:44:00,001 basehttp 161 "GET /static/rest_framework/css/prettify.css HTTP/1.1" 304 0
INFO 2021-06-10 00:44:00,007 basehttp 161 "GET /static/rest_framework/css/default.css HTTP/1.1" 304 0
INFO 2021-06-10 00:44:00,007 basehttp 161 "GET /static/rest_framework/js/csrf.js HTTP/1.1" 304 0
INFO 2021-06-10 00:44:00,015 basehttp 161 "GET /static/rest_framework/js/prettify-min.js HTTP/1.1" 304 0
INFO 2021-06-10 00:44:00,015 basehttp 161 "GET /static/rest_framework/js/jquery-3.5.1.min.js HTTP/1.1" 304 0
INFO 2021-06-10 00:44:00,016 basehttp 161 "GET /static/rest_framework/js/bootstrap.min.js HTTP/1.1" 304 0
INFO 2021-06-10 00:44:00,017 basehttp 161 "GET /static/rest_framework/js/ajax-form.js HTTP/1.1" 304 0
INFO 2021-06-10 00:44:00,020 basehttp 161 "GET /static/rest_framework/js/default.js HTTP/1.1" 304 0
INFO 2021-06-10 00:44:00,036 basehttp 161 "GET /static/rest_framework/img/grid.png HTTP/1.1" 304 0
INFO 2021-06-10 00:44:01,864 basehttp 161 "GET /login/login/?next=/interfaces/ HTTP/1.1" 200 2708
INFO 2021-06-10 00:48:08,470 autoreload 636 Watching for file changes with StatReloader
WARNING 2021-06-10 00:48:10,596 log 224 Not Found: /
WARNING 2021-06-10 00:48:10,598 basehttp 161 "GET / HTTP/1.1" 404 2381
WARNING 2021-06-10 00:48:16,311 log 224 Not Found: /login/
WARNING 2021-06-10 00:48:16,313 basehttp 161 "GET /login/ HTTP/1.1" 404 2659
WARNING 2021-06-10 00:48:42,220 log 224 Forbidden: /interfaces/
WARNING 2021-06-10 00:48:42,223 basehttp 161 "GET /interfaces/ HTTP/1.1" 403 5045
INFO 2021-06-10 00:48:44,669 basehttp 161 "GET /login/login/?next=/interfaces/ HTTP/1.1" 200 2708
INFO 2021-06-10 00:50:28,003 autoreload 636 Watching for file changes with StatReloader
WARNING 2021-06-10 00:52:59,643 log 224 Not Found: /
WARNING 2021-06-10 00:52:59,645 basehttp 161 "GET / HTTP/1.1" 404 2381
WARNING 2021-06-10 00:53:07,392 log 224 Forbidden: /docs
WARNING 2021-06-10 00:53:07,393 basehttp 161 "GET /docs HTTP/1.1" 403 4943
INFO 2021-06-10 00:53:20,660 basehttp 161 "GET /login/login/?next=/docs HTTP/1.1" 200 2701
WARNING 2021-06-10 00:54:13,693 basehttp 161 "GET /static/rest_framework/css/bootstrap.min.css.map HTTP/1.1" 404 1879
INFO 2021-06-10 00:54:26,951 basehttp 161 "POST /login/login/ HTTP/1.1" 302 0
INFO 2021-06-10 00:54:27,218 basehttp 161 "GET /docs HTTP/1.1" 200 92617
INFO 2021-06-10 00:54:27,372 basehttp 161 "GET /docsschema.js HTTP/1.1" 200 11736
INFO 2021-06-10 00:54:28,695 basehttp 161 "GET /static/rest_framework/docs/css/base.css HTTP/1.1" 200 6147
INFO 2021-06-10 00:54:28,697 basehttp 161 "GET /static/rest_framework/css/bootstrap-theme.min.css HTTP/1.1" 200 23411
INFO 2021-06-10 00:54:28,700 basehttp 161 "GET /static/rest_framework/docs/css/jquery.json-view.min.css HTTP/1.1" 200 1307
INFO 2021-06-10 00:54:28,709 basehttp 161 "GET /static/rest_framework/css/font-awesome-4.0.3.css HTTP/1.1" 200 21658
INFO 2021-06-10 00:54:28,715 basehttp 161 "GET /static/rest_framework/docs/js/api.js HTTP/1.1" 200 10539
INFO 2021-06-10 00:54:28,719 basehttp 161 "GET /static/rest_framework/js/coreapi-0.1.1.js HTTP/1.1" 200 157600
INFO 2021-06-10 00:54:28,732 basehttp 161 "GET /static/rest_framework/docs/js/jquery.json-view.min.js HTTP/1.1" 200 2700
WARNING 2021-06-10 00:54:28,811 basehttp 161 "GET /static/rest_framework/css/bootstrap.min.css.map HTTP/1.1" 404 1879
WARNING 2021-06-10 00:54:28,811 basehttp 161 "GET /static/rest_framework/css/bootstrap-theme.min.css.map HTTP/1.1" 404 1897
INFO 2021-06-10 00:54:28,816 basehttp 161 "GET /static/rest_framework/fonts/fontawesome-webfont.woff?v=4.0.3 HTTP/1.1" 200 44432
INFO 2021-06-10 00:54:28,969 basehttp 161 "GET /static/rest_framework/docs/img/favicon.ico HTTP/1.1" 200 5430
WARNING 2021-06-10 00:55:29,605 log 224 Forbidden (CSRF cookie not set.): /login/login/
WARNING 2021-06-10 00:55:29,607 basehttp 161 "POST /login/login/ HTTP/1.1" 403 2801
INFO 2021-06-12 07:14:58,075 autoreload 636 Watching for file changes with StatReloader
INFO 2021-06-12 07:24:45,130 autoreload 636 Watching for file changes with StatReloader
INFO 2021-06-12 07:25:38,904 autoreload 636 Watching for file changes with StatReloader
WARNING 2021-06-12 07:26:34,509 log 224 Forbidden: /projects/1/
WARNING 2021-06-12 07:26:34,512 basehttp 161 "PATCH /projects/1/ HTTP/1.1" 403 43
WARNING 2021-06-12 07:26:43,862 log 224 Not Found: /
WARNING 2021-06-12 07:26:43,864 basehttp 161 "GET / HTTP/1.1" 404 2486
WARNING 2021-06-12 07:26:43,981 log 224 Not Found: /favicon.ico
WARNING 2021-06-12 07:26:43,983 basehttp 161 "GET /favicon.ico HTTP/1.1" 404 2537
INFO 2021-06-12 07:26:52,742 basehttp 161 "GET /interfaces/ HTTP/1.1" 200 13445
INFO 2021-06-12 07:26:52,806 basehttp 161 "GET /static/rest_framework/css/bootstrap.min.css HTTP/1.1" 304 0
INFO 2021-06-12 07:26:52,807 basehttp 161 "GET /static/rest_framework/css/bootstrap-tweaks.css HTTP/1.1" 304 0
INFO 2021-06-12 07:26:52,809 basehttp 161 "GET /static/rest_framework/css/prettify.css HTTP/1.1" 304 0
INFO 2021-06-12 07:26:52,813 basehttp 161 "GET /static/rest_framework/css/default.css HTTP/1.1" 304 0
INFO 2021-06-12 07:26:52,821 basehttp 161 "GET /static/rest_framework/js/jquery-3.5.1.min.js HTTP/1.1" 304 0
INFO 2021-06-12 07:26:52,821 basehttp 161 "GET /static/rest_framework/js/csrf.js HTTP/1.1" 304 0
INFO 2021-06-12 07:26:52,831 basehttp 161 "GET /static/rest_framework/js/bootstrap.min.js HTTP/1.1" 304 0
INFO 2021-06-12 07:26:52,833 basehttp 161 "GET /static/rest_framework/js/ajax-form.js HTTP/1.1" 304 0
INFO 2021-06-12 07:26:52,834 basehttp 161 "GET /static/rest_framework/js/prettify-min.js HTTP/1.1" 304 0
INFO 2021-06-12 07:26:52,835 basehttp 161 "GET /static/rest_framework/js/default.js HTTP/1.1" 304 0
INFO 2021-06-12 07:26:52,848 basehttp 161 "GET /static/rest_framework/img/grid.png HTTP/1.1" 304 0
INFO 2021-06-12 07:26:53,241 basehttp 161 "GET /static/rest_framework/fonts/glyphicons-halflings-regular.woff2 HTTP/1.1" 200 18028
INFO 2021-06-12 07:27:09,711 basehttp 161 "GET /login/logout/?next=/interfaces/ HTTP/1.1" 302 0
WARNING 2021-06-12 07:27:09,744 log 224 Forbidden: /interfaces/
WARNING 2021-06-12 07:27:09,746 basehttp 161 "GET /interfaces/ HTTP/1.1" 403 5045
INFO 2021-06-12 07:27:11,547 basehttp 161 "GET /login/login/?next=/interfaces/ HTTP/1.1" 200 2708
WARNING 2021-06-12 07:28:16,375 log 224 Not Found: /user/
WARNING 2021-06-12 07:28:16,377 basehttp 161 "GET /user/ HTTP/1.1" 404 2572
WARNING 2021-06-12 07:28:35,219 log 224 Method Not Allowed: /user/login/
WARNING 2021-06-12 07:28:35,220 basehttp 161 "GET /user/login/ HTTP/1.1" 405 7730
INFO 2021-06-12 07:34:43,441 autoreload 636 Watching for file changes with StatReloader
INFO 2021-06-12 07:34:50,305 basehttp 161 "POST /user/login/ HTTP/1.1" 200 197
WARNING 2021-06-12 07:37:55,792 log 224 Forbidden (CSRF cookie not set.): /login/login/
WARNING 2021-06-12 07:37:55,794 basehttp 161 "POST /login/login/ HTTP/1.1" 403 2801
WARNING 2021-06-12 07:38:33,452 log 224 Forbidden (CSRF cookie not set.): /login/login/
WARNING 2021-06-12 07:38:33,454 basehttp 161 "POST /login/login/ HTTP/1.1" 403 2801
WARNING 2021-06-12 07:39:11,003 log 224 Forbidden (CSRF cookie not set.): /login/login/
WARNING 2021-06-12 07:39:11,004 basehttp 161 "POST /login/login/ HTTP/1.1" 403 2801
WARNING 2021-06-12 07:39:35,361 log 224 Not Found: /
WARNING 2021-06-12 07:39:35,363 basehttp 161 "GET / HTTP/1.1" 404 2486
WARNING 2021-06-12 07:39:43,821 log 224 Not Found: /login/
WARNING 2021-06-12 07:39:43,822 basehttp 161 "GET /login/ HTTP/1.1" 404 2764
INFO 2021-06-12 07:39:48,588 basehttp 161 "GET /login/login/ HTTP/1.1" 200 2696
INFO 2021-06-12 07:39:56,147 basehttp 161 "GET /login/login/ HTTP/1.1" 200 2696
WARNING 2021-06-12 07:39:59,458 basehttp 161 "GET /static/rest_framework/css/bootstrap.min.css.map HTTP/1.1" 404 1879
INFO 2021-06-12 07:40:13,133 basehttp 161 "POST /login/login/ HTTP/1.1" 302 0
WARNING 2021-06-12 07:40:13,150 log 224 Not Found: /accounts/profile/
WARNING 2021-06-12 07:40:13,152 basehttp 161 "GET /accounts/profile/ HTTP/1.1" 404 2555
INFO 2021-06-12 07:40:50,749 basehttp 161 "GET /interfaces/ HTTP/1.1" 200 13445
WARNING 2021-06-12 07:40:50,889 basehttp 161 "GET /static/rest_framework/css/bootstrap.min.css.map HTTP/1.1" 404 1879
INFO 2021-06-12 07:40:55,977 basehttp 161 "GET /login/logout/?next=/interfaces/ HTTP/1.1" 302 0
WARNING 2021-06-12 07:40:56,008 log 224 Forbidden: /interfaces/
WARNING 2021-06-12 07:40:56,009 basehttp 161 "GET /interfaces/ HTTP/1.1" 403 5045
WARNING 2021-06-12 07:40:56,110 basehttp 161 "GET /static/rest_framework/css/bootstrap.min.css.map HTTP/1.1" 404 1879
INFO 2021-06-12 07:40:59,772 basehttp 161 "GET /login/login/?next=/interfaces/ HTTP/1.1" 200 2708
WARNING 2021-06-12 07:40:59,877 basehttp 161 "GET /static/rest_framework/css/bootstrap.min.css.map HTTP/1.1" 404 1879
INFO 2021-06-12 07:41:11,786 basehttp 161 "POST /login/login/ HTTP/1.1" 302 0
INFO 2021-06-12 07:41:11,930 basehttp 161 "GET /interfaces/ HTTP/1.1" 200 13445
WARNING 2021-06-12 07:41:12,028 basehttp 161 "GET /static/rest_framework/css/bootstrap.min.css.map HTTP/1.1" 404 1879
INFO 2021-06-12 07:41:58,000 autoreload 250 F:\Python\Python_Project\python_test_developer\main\urls.py changed, reloading.
INFO 2021-06-12 07:42:00,291 autoreload 636 Watching for file changes with StatReloader
INFO 2021-06-12 07:42:02,970 autoreload 250 F:\Python\Python_Project\python_test_developer\main\urls.py changed, reloading.
INFO 2021-06-12 07:42:05,458 autoreload 636 Watching for file changes with StatReloader
INFO 2021-06-12 07:42:08,343 autoreload 250 F:\Python\Python_Project\python_test_developer\main\urls.py changed, reloading.
INFO 2021-06-12 07:42:10,647 autoreload 636 Watching for file changes with StatReloader
INFO 2021-06-12 07:42:13,347 autoreload 250 F:\Python\Python_Project\python_test_developer\main\urls.py changed, reloading.
INFO 2021-06-12 07:42:15,712 autoreload 636 Watching for file changes with StatReloader
INFO 2021-06-12 07:42:22,000 autoreload 250 F:\Python\Python_Project\python_test_developer\main\urls.py changed, reloading.
INFO 2021-06-12 07:42:24,276 autoreload 636 Watching for file changes with StatReloader
INFO 2021-06-12 07:42:31,795 autoreload 250 F:\Python\Python_Project\python_test_developer\main\urls.py changed, reloading.
INFO 2021-06-12 07:42:34,085 autoreload 636 Watching for file changes with StatReloader
INFO 2021-06-12 07:42:38,024 autoreload 250 F:\Python\Python_Project\python_test_developer\main\urls.py changed, reloading.
INFO 2021-06-12 07:42:40,173 autoreload 636 Watching for file changes with StatReloader
INFO 2021-06-12 07:42:47,655 autoreload 250 F:\Python\Python_Project\python_test_developer\main\urls.py changed, reloading.
INFO 2021-06-12 07:42:50,061 autoreload 636 Watching for file changes with StatReloader
INFO 2021-06-12 07:42:52,856 autoreload 250 F:\Python\Python_Project\python_test_developer\main\urls.py changed, reloading.
INFO 2021-06-12 07:42:55,223 autoreload 636 Watching for file changes with StatReloader
INFO 2021-06-12 07:42:57,991 autoreload 250 F:\Python\Python_Project\python_test_developer\main\urls.py changed, reloading.
INFO 2021-06-12 07:43:00,304 autoreload 636 Watching for file changes with StatReloader
INFO 2021-06-12 07:43:07,748 autoreload 250 F:\Python\Python_Project\python_test_developer\main\urls.py changed, reloading.
INFO 2021-06-12 07:43:10,179 autoreload 636 Watching for file changes with StatReloader
INFO 2021-06-12 07:43:20,011 autoreload 250 F:\Python\Python_Project\python_test_developer\main\urls.py changed, reloading.
INFO 2021-06-12 07:43:22,480 autoreload 636 Watching for file changes with StatReloader
INFO 2021-06-12 07:43:25,217 autoreload 250 F:\Python\Python_Project\python_test_developer\main\urls.py changed, reloading.
INFO 2021-06-12 07:43:27,622 autoreload 636 Watching for file changes with StatReloader
INFO 2021-06-12 17:34:45,461 autoreload 636 Watching for file changes with StatReloader
WARNING 2021-06-12 17:44:05,891 log 224 Not Found: /user/register/
WARNING 2021-06-12 17:44:05,894 basehttp 161 "POST /user/register/ HTTP/1.1" 404 2732
INFO 2021-06-12 17:44:40,560 autoreload 636 Watching for file changes with StatReloader
WARNING 2021-06-12 17:45:46,094 log 224 Not Found: /user/register/
WARNING 2021-06-12 17:45:46,097 basehttp 161 "POST /user/register/ HTTP/1.1" 404 2732
INFO 2021-06-12 17:46:21,712 autoreload 636 Watching for file changes with StatReloader
WARNING 2021-06-12 17:46:24,974 log 224 Not Found: /user/register/
WARNING 2021-06-12 17:46:24,976 basehttp 161 "POST /user/register/ HTTP/1.1" 404 2730
INFO 2021-06-12 17:46:54,141 autoreload 250 F:\Python\Python_Project\python_test_developer\users\urls.py changed, reloading.
INFO 2021-06-12 17:47:41,425 autoreload 636 Watching for file changes with StatReloader
WARNING 2021-06-12 17:47:45,962 log 224 Not Found: /user/register/
WARNING 2021-06-12 17:47:45,965 basehttp 161 "POST /user/register/ HTTP/1.1" 404 2732
INFO 2021-06-12 17:48:01,433 basehttp 161 "POST /user/login/ HTTP/1.1" 200 197
WARNING 2021-06-12 17:49:16,188 log 224 Not Found: /user/register/
WARNING 2021-06-12 17:49:16,190 basehttp 161 "POST /user/register/ HTTP/1.1" 404 2732
WARNING 2021-06-12 17:49:25,727 log 224 Not Found: /user/register/
WARNING 2021-06-12 17:49:25,728 basehttp 161 "GET /user/register/ HTTP/1.1" 404 2731
INFO 2021-06-12 17:51:04,660 autoreload 250 F:\Python\Python_Project\python_test_developer\users\urls.py changed, reloading.
INFO 2021-06-12 17:51:07,095 autoreload 636 Watching for file changes with StatReloader
WARNING 2021-06-12 17:51:13,599 log 224 Not Found: /
WARNING 2021-06-12 17:51:13,601 basehttp 161 "GET / HTTP/1.1" 404 2380
INFO 2021-06-12 17:51:46,679 autoreload 636 Watching for file changes with StatReloader
WARNING 2021-06-12 17:51:51,347 log 224 Not Found: /
WARNING 2021-06-12 17:51:51,350 basehttp 161 "GET / HTTP/1.1" 404 2380
WARNING 2021-06-12 17:51:59,805 log 224 Not Found: /user
WARNING 2021-06-12 17:51:59,806 basehttp 161 "GET /user HTTP/1.1" 404 2410
WARNING 2021-06-12 17:52:06,269 log 224 Not Found: /user/
WARNING 2021-06-12 17:52:06,270 basehttp 161 "GET /user/ HTTP/1.1" 404 2626
WARNING 2021-06-12 17:52:21,665 log 224 Not Found: /user/reguster
WARNING 2021-06-12 17:52:21,667 basehttp 161 "GET /user/reguster HTTP/1.1" 404 2650
WARNING 2021-06-12 17:52:31,173 log 224 Not Found: /user/register
WARNING 2021-06-12 17:52:31,175 basehttp 161 "GET /user/register HTTP/1.1" 404 2726
WARNING 2021-06-12 17:54:15,169 log 224 Method Not Allowed: /user/login/
WARNING 2021-06-12 17:54:15,170 basehttp 161 "GET /user/login/ HTTP/1.1" 405 7669
INFO 2021-06-12 17:54:45,451 autoreload 250 F:\Python\Python_Project\python_test_developer\users\urls.py changed, reloading.
INFO 2021-06-12 17:54:47,861 autoreload 636 Watching for file changes with StatReloader
INFO 2021-06-12 17:54:54,542 basehttp 161 "GET /user/register HTTP/1.1" 301 0
WARNING 2021-06-12 17:54:55,176 log 224 Method Not Allowed: /user/register/
WARNING 2021-06-12 17:54:55,177 basehttp 161 "GET /user/register/ HTTP/1.1" 405 14913
INFO 2021-06-12 17:56:34,896 autoreload 250 F:\Python\Python_Project\python_test_developer\users\urls.py changed, reloading.
INFO 2021-06-12 17:56:37,180 autoreload 636 Watching for file changes with StatReloader
WARNING 2021-06-12 17:56:42,173 log 224 Not Found: /user/reguster
WARNING 2021-06-12 17:56:42,176 basehttp 161 "GET /user/reguster HTTP/1.1" 404 2651
WARNING 2021-06-12 17:56:47,429 log 224 Not Found: /user/reguster/
WARNING 2021-06-12 17:56:47,430 basehttp 161 "GET /user/reguster/ HTTP/1.1" 404 2654
WARNING 2021-06-12 17:57:12,438 log 224 Not Found: /user/reguster/reguster
WARNING 2021-06-12 17:57:12,439 basehttp 161 "GET /user/reguster/reguster HTTP/1.1" 404 2678
WARNING 2021-06-12 17:57:19,030 log 224 Not Found: /user/reguster reguster/
WARNING 2021-06-12 17:57:19,031 basehttp 161 "GET /user/reguster%20reguster/ HTTP/1.1" 404 2683
INFO 2021-06-12 17:57:26,367 autoreload 636 Watching for file changes with StatReloader
WARNING 2021-06-12 17:57:29,863 log 224 Not Found: /user/reguster
WARNING 2021-06-12 17:57:29,865 basehttp 161 "GET /user/reguster HTTP/1.1" 404 2651
WARNING 2021-06-12 17:57:33,300 log 224 Not Found: /user/reguster/
WARNING 2021-06-12 17:57:33,302 basehttp 161 "GET /user/reguster/ HTTP/1.1" 404 2654
INFO 2021-06-12 17:57:48,882 autoreload 250 F:\Python\Python_Project\python_test_developer\users\urls.py changed, reloading.
INFO 2021-06-12 17:57:51,215 autoreload 636 Watching for file changes with StatReloader
WARNING 2021-06-12 17:57:54,111 log 224 Not Found: /user/reguster/
WARNING 2021-06-12 17:57:54,113 basehttp 161 "GET /user/reguster/ HTTP/1.1" 404 2654
WARNING 2021-06-12 17:57:56,977 log 224 Not Found: /
WARNING 2021-06-12 17:57:56,979 basehttp 161 "GET / HTTP/1.1" 404 2380
WARNING 2021-06-12 17:58:05,567 log 224 Not Found: /user/
WARNING 2021-06-12 17:58:05,568 basehttp 161 "GET /user/ HTTP/1.1" 404 2627
WARNING 2021-06-12 17:58:15,909 log 224 Not Found: /user/register/
WARNING 2021-06-12 17:58:15,910 basehttp 161 "GET /user/register/ HTTP/1.1" 404 2731
WARNING 2021-06-12 17:58:29,974 log 224 Not Found: /user/register/register/
WARNING 2021-06-12 17:58:29,975 basehttp 161 "GET /user/register/register/ HTTP/1.1" 404 2758
WARNING 2021-06-12 17:59:03,879 log 224 Method Not Allowed: /user/register/register//
WARNING 2021-06-12 17:59:03,881 basehttp 161 "GET /user/register/register// HTTP/1.1" 405 14963
INFO 2021-06-12 17:59:20,486 autoreload 250 F:\Python\Python_Project\python_test_developer\users\urls.py changed, reloading.
INFO 2021-06-12 17:59:22,992 autoreload 636 Watching for file changes with StatReloader
INFO 2021-06-12 18:02:19,511 autoreload 636 Watching for file changes with StatReloader
INFO 2021-06-12 18:06:40,204 autoreload 636 Watching for file changes with StatReloader
WARNING 2021-06-12 18:06:46,035 log 224 Bad Request: /user/register/
WARNING 2021-06-12 18:06:46,037 basehttp 161 "POST /user/register/ HTTP/1.1" 400 109
INFO 2021-06-12 18:10:28,521 autoreload 250 F:\Python\Python_Project\python_test_developer\users\views.py changed, reloading.
ERROR 2021-06-12 18:10:48,472 log 224 Internal Server Error: /user/register/
Traceback (most recent call last):
  File "F:\Python\Python_Venv\Django_AutoTest\lib\site-packages\django\core\handlers\exception.py", line 47, in inner
    response = get_response(request)
  File "F:\Python\Python_Venv\Django_AutoTest\lib\site-packages\django\core\handlers\base.py", line 181, in _get_response
    response = wrapped_callback(request, *callback_args, **callback_kwargs)
  File "F:\Python\Python_Venv\Django_AutoTest\lib\site-packages\django\views\decorators\csrf.py", line 54, in wrapped_view
    return view_func(*args, **kwargs)
  File "F:\Python\Python_Venv\Django_AutoTest\lib\site-packages\rest_framework\viewsets.py", line 125, in view
    return self.dispatch(request, *args, **kwargs)
  File "F:\Python\Python_Venv\Django_AutoTest\lib\site-packages\rest_framework\views.py", line 509, in dispatch
    response = self.handle_exception(exc)
  File "F:\Python\Python_Venv\Django_AutoTest\lib\site-packages\rest_framework\views.py", line 469, in handle_exception
    self.raise_uncaught_exception(exc)
  File "F:\Python\Python_Venv\Django_AutoTest\lib\site-packages\rest_framework\views.py", line 480, in raise_uncaught_exception
    raise exc
  File "F:\Python\Python_Venv\Django_AutoTest\lib\site-packages\rest_framework\views.py", line 506, in dispatch
    response = handler(request, *args, **kwargs)
  File "F:\Python\Python_Project\python_test_developer\users\views.py", line 21, in create
    email = request.POST.get('email')
  File "F:\Python\Python_Venv\Django_AutoTest\lib\site-packages\django\contrib\auth\models.py", line 152, in create_user
    return self._create_user(username, email, password, **extra_fields)
  File "F:\Python\Python_Venv\Django_AutoTest\lib\site-packages\django\contrib\auth\models.py", line 137, in _create_user
    raise ValueError('The given username must be set')
ValueError: The given username must be set
INFO 2021-06-12 18:10:48,482 basehttp 75 - Broken pipe from ('127.0.0.1', 5309)

INFO 2021-06-12 18:10:50,346 autoreload 636 Watching for file changes with StatReloader
INFO 2021-06-12 18:13:02,657 autoreload 636 Watching for file changes with StatReloader
WARNING 2021-06-12 18:13:05,349 log 224 Bad Request: /user/register/
WARNING 2021-06-12 18:13:05,352 basehttp 161 "POST /user/register/ HTTP/1.1" 400 109
WARNING 2021-06-12 18:13:22,690 log 224 Bad Request: /user/register/
WARNING 2021-06-12 18:13:22,692 basehttp 161 "POST /user/register/ HTTP/1.1" 400 55
INFO 2021-06-12 18:14:28,249 autoreload 250 F:\Python\Python_Project\python_test_developer\users\serializers.py changed, reloading.
INFO 2021-06-12 18:14:30,472 autoreload 636 Watching for file changes with StatReloader
INFO 2021-06-12 18:14:43,847 autoreload 636 Watching for file changes with StatReloader
ERROR 2021-06-12 18:14:51,239 log 224 Internal Server Error: /user/register/
Traceback (most recent call last):
  File "F:\Python\Python_Venv\Django_AutoTest\lib\site-packages\django\core\handlers\exception.py", line 47, in inner
    response = get_response(request)
  File "F:\Python\Python_Venv\Django_AutoTest\lib\site-packages\django\core\handlers\base.py", line 181, in _get_response
    response = wrapped_callback(request, *callback_args, **callback_kwargs)
  File "F:\Python\Python_Venv\Django_AutoTest\lib\site-packages\django\views\decorators\csrf.py", line 54, in wrapped_view
    return view_func(*args, **kwargs)
  File "F:\Python\Python_Venv\Django_AutoTest\lib\site-packages\rest_framework\viewsets.py", line 125, in view
    return self.dispatch(request, *args, **kwargs)
  File "F:\Python\Python_Venv\Django_AutoTest\lib\site-packages\rest_framework\views.py", line 509, in dispatch
    response = self.handle_exception(exc)
  File "F:\Python\Python_Venv\Django_AutoTest\lib\site-packages\rest_framework\views.py", line 469, in handle_exception
    self.raise_uncaught_exception(exc)
  File "F:\Python\Python_Venv\Django_AutoTest\lib\site-packages\rest_framework\views.py", line 480, in raise_uncaught_exception
    raise exc
  File "F:\Python\Python_Venv\Django_AutoTest\lib\site-packages\rest_framework\views.py", line 506, in dispatch
    response = handler(request, *args, **kwargs)
  File "F:\Python\Python_Project\python_test_developer\users\views.py", line 19, in create
    serializer.is_valid(raise_exception=True)
  File "F:\Python\Python_Venv\Django_AutoTest\lib\site-packages\rest_framework\serializers.py", line 220, in is_valid
    self._validated_data = self.run_validation(self.initial_data)
  File "F:\Python\Python_Venv\Django_AutoTest\lib\site-packages\rest_framework\serializers.py", line 419, in run_validation
    value = self.to_internal_value(data)
  File "F:\Python\Python_Venv\Django_AutoTest\lib\site-packages\rest_framework\serializers.py", line 476, in to_internal_value
    validated_value = field.run_validation(primitive_value)
  File "F:\Python\Python_Venv\Django_AutoTest\lib\site-packages\rest_framework\fields.py", line 799, in run_validation
    return super().run_validation(data)
  File "F:\Python\Python_Venv\Django_AutoTest\lib\site-packages\rest_framework\fields.py", line 569, in run_validation
    self.run_validators(value)
  File "F:\Python\Python_Venv\Django_AutoTest\lib\site-packages\rest_framework\fields.py", line 593, in run_validators
    validator(value)
TypeError: validate_password_check() missing 1 required positional argument: 'attr'
ERROR 2021-06-12 18:14:51,249 basehttp 161 "POST /user/register/ HTTP/1.1" 500 134426
INFO 2021-06-12 18:19:14,135 autoreload 250 F:\Python\Python_Project\python_test_developer\users\serializers.py changed, reloading.
INFO 2021-06-12 18:19:16,337 autoreload 636 Watching for file changes with StatReloader
INFO 2021-06-12 18:19:35,758 autoreload 636 Watching for file changes with StatReloader
ERROR 2021-06-12 18:19:42,917 log 224 Internal Server Error: /user/register/
Traceback (most recent call last):
  File "F:\Python\Python_Venv\Django_AutoTest\lib\site-packages\django\core\handlers\exception.py", line 47, in inner
    response = get_response(request)
  File "F:\Python\Python_Venv\Django_AutoTest\lib\site-packages\django\core\handlers\base.py", line 181, in _get_response
    response = wrapped_callback(request, *callback_args, **callback_kwargs)
  File "F:\Python\Python_Venv\Django_AutoTest\lib\site-packages\django\views\decorators\csrf.py", line 54, in wrapped_view
    return view_func(*args, **kwargs)
  File "F:\Python\Python_Venv\Django_AutoTest\lib\site-packages\rest_framework\viewsets.py", line 125, in view
    return self.dispatch(request, *args, **kwargs)
  File "F:\Python\Python_Venv\Django_AutoTest\lib\site-packages\rest_framework\views.py", line 509, in dispatch
    response = self.handle_exception(exc)
  File "F:\Python\Python_Venv\Django_AutoTest\lib\site-packages\rest_framework\views.py", line 469, in handle_exception
    self.raise_uncaught_exception(exc)
  File "F:\Python\Python_Venv\Django_AutoTest\lib\site-packages\rest_framework\views.py", line 480, in raise_uncaught_exception
    raise exc
  File "F:\Python\Python_Venv\Django_AutoTest\lib\site-packages\rest_framework\views.py", line 506, in dispatch
    response = handler(request, *args, **kwargs)
  File "F:\Python\Python_Project\python_test_developer\users\views.py", line 19, in create
    serializer.is_valid(raise_exception=True)
  File "F:\Python\Python_Venv\Django_AutoTest\lib\site-packages\rest_framework\serializers.py", line 220, in is_valid
    self._validated_data = self.run_validation(self.initial_data)
  File "F:\Python\Python_Venv\Django_AutoTest\lib\site-packages\rest_framework\serializers.py", line 419, in run_validation
    value = self.to_internal_value(data)
  File "F:\Python\Python_Venv\Django_AutoTest\lib\site-packages\rest_framework\serializers.py", line 476, in to_internal_value
    validated_value = field.run_validation(primitive_value)
  File "F:\Python\Python_Venv\Django_AutoTest\lib\site-packages\rest_framework\fields.py", line 799, in run_validation
    return super().run_validation(data)
  File "F:\Python\Python_Venv\Django_AutoTest\lib\site-packages\rest_framework\fields.py", line 569, in run_validation
    self.run_validators(value)
  File "F:\Python\Python_Venv\Django_AutoTest\lib\site-packages\rest_framework\fields.py", line 593, in run_validators
    validator(value)
TypeError: 'classmethod' object is not callable
ERROR 2021-06-12 18:19:42,927 basehttp 161 "POST /user/register/ HTTP/1.1" 500 133841
INFO 2021-06-12 18:20:16,892 autoreload 250 F:\Python\Python_Project\python_test_developer\users\serializers.py changed, reloading.
INFO 2021-06-12 18:20:39,717 autoreload 636 Watching for file changes with StatReloader
ERROR 2021-06-12 18:21:03,518 log 224 Internal Server Error: /user/register/
Traceback (most recent call last):
  File "F:\Python\Python_Venv\Django_AutoTest\lib\site-packages\django\core\handlers\exception.py", line 47, in inner
    response = get_response(request)
  File "F:\Python\Python_Venv\Django_AutoTest\lib\site-packages\django\core\handlers\base.py", line 181, in _get_response
    response = wrapped_callback(request, *callback_args, **callback_kwargs)
  File "F:\Python\Python_Venv\Django_AutoTest\lib\site-packages\django\views\decorators\csrf.py", line 54, in wrapped_view
    return view_func(*args, **kwargs)
  File "F:\Python\Python_Venv\Django_AutoTest\lib\site-packages\rest_framework\viewsets.py", line 125, in view
    return self.dispatch(request, *args, **kwargs)
  File "F:\Python\Python_Venv\Django_AutoTest\lib\site-packages\rest_framework\views.py", line 509, in dispatch
    response = self.handle_exception(exc)
  File "F:\Python\Python_Venv\Django_AutoTest\lib\site-packages\rest_framework\views.py", line 469, in handle_exception
    self.raise_uncaught_exception(exc)
  File "F:\Python\Python_Venv\Django_AutoTest\lib\site-packages\rest_framework\views.py", line 480, in raise_uncaught_exception
    raise exc
  File "F:\Python\Python_Venv\Django_AutoTest\lib\site-packages\rest_framework\views.py", line 506, in dispatch
    response = handler(request, *args, **kwargs)
  File "F:\Python\Python_Project\python_test_developer\users\views.py", line 19, in create
    serializer.is_valid(raise_exception=True)
  File "F:\Python\Python_Venv\Django_AutoTest\lib\site-packages\rest_framework\serializers.py", line 220, in is_valid
    self._validated_data = self.run_validation(self.initial_data)
  File "F:\Python\Python_Venv\Django_AutoTest\lib\site-packages\rest_framework\serializers.py", line 419, in run_validation
    value = self.to_internal_value(data)
  File "F:\Python\Python_Venv\Django_AutoTest\lib\site-packages\rest_framework\serializers.py", line 476, in to_internal_value
    validated_value = field.run_validation(primitive_value)
  File "F:\Python\Python_Venv\Django_AutoTest\lib\site-packages\rest_framework\fields.py", line 799, in run_validation
    return super().run_validation(data)
  File "F:\Python\Python_Venv\Django_AutoTest\lib\site-packages\rest_framework\fields.py", line 569, in run_validation
    self.run_validators(value)
  File "F:\Python\Python_Venv\Django_AutoTest\lib\site-packages\rest_framework\fields.py", line 593, in run_validators
    validator(value)
  File "F:\Python\Python_Project\python_test_developer\users\serializers.py", line 12, in validate_password_check
    if attr == UserRegisterModelSeralizer.username:
AttributeError: type object 'UserRegisterModelSeralizer' has no attribute 'username'
ERROR 2021-06-12 18:21:03,534 basehttp 161 "POST /user/register/ HTTP/1.1" 500 138446
INFO 2021-06-12 18:23:58,571 autoreload 250 F:\Python\Python_Project\python_test_developer\users\serializers.py changed, reloading.
INFO 2021-06-12 18:24:01,093 autoreload 636 Watching for file changes with StatReloader
ERROR 2021-06-12 18:24:19,220 log 224 Internal Server Error: /user/register/
Traceback (most recent call last):
  File "F:\Python\Python_Venv\Django_AutoTest\lib\site-packages\django\core\handlers\exception.py", line 47, in inner
    response = get_response(request)
  File "F:\Python\Python_Venv\Django_AutoTest\lib\site-packages\django\core\handlers\base.py", line 181, in _get_response
    response = wrapped_callback(request, *callback_args, **callback_kwargs)
  File "F:\Python\Python_Venv\Django_AutoTest\lib\site-packages\django\views\decorators\csrf.py", line 54, in wrapped_view
    return view_func(*args, **kwargs)
  File "F:\Python\Python_Venv\Django_AutoTest\lib\site-packages\rest_framework\viewsets.py", line 125, in view
    return self.dispatch(request, *args, **kwargs)
  File "F:\Python\Python_Venv\Django_AutoTest\lib\site-packages\rest_framework\views.py", line 509, in dispatch
    response = self.handle_exception(exc)
  File "F:\Python\Python_Venv\Django_AutoTest\lib\site-packages\rest_framework\views.py", line 469, in handle_exception
    self.raise_uncaught_exception(exc)
  File "F:\Python\Python_Venv\Django_AutoTest\lib\site-packages\rest_framework\views.py", line 480, in raise_uncaught_exception
    raise exc
  File "F:\Python\Python_Venv\Django_AutoTest\lib\site-packages\rest_framework\views.py", line 506, in dispatch
    response = handler(request, *args, **kwargs)
  File "F:\Python\Python_Project\python_test_developer\users\views.py", line 19, in create
    6        serializer.is_valid(raise_exception=True)
  File "F:\Python\Python_Venv\Django_AutoTest\lib\site-packages\rest_framework\serializers.py", line 220, in is_valid
    self._validated_data = self.run_validation(self.initial_data)
  File "F:\Python\Python_Venv\Django_AutoTest\lib\site-packages\rest_framework\serializers.py", line 419, in run_validation
    value = self.to_internal_value(data)
  File "F:\Python\Python_Venv\Django_AutoTest\lib\site-packages\rest_framework\serializers.py", line 476, in to_internal_value
    validated_value = field.run_validation(primitive_value)
  File "F:\Python\Python_Venv\Django_AutoTest\lib\site-packages\rest_framework\fields.py", line 799, in run_validation
    return super().run_validation(data)
  File "F:\Python\Python_Venv\Django_AutoTest\lib\site-packages\rest_framework\fields.py", line 569, in run_validation
    self.run_validators(value)
  File "F:\Python\Python_Venv\Django_AutoTest\lib\site-packages\rest_framework\fields.py", line 593, in run_validators
    validator(value)
  File "F:\Python\Python_Project\python_test_developer\users\serializers.py", line 12, in validate_password_check
    if attr == serializers.username:
AttributeError: module 'rest_framework.serializers' has no attribute 'username'
ERROR 2021-06-12 18:24:19,237 basehttp 161 "POST /user/register/ HTTP/1.1" 500 138386
INFO 2021-06-12 18:24:20,231 autoreload 250 F:\Python\Python_Project\python_test_developer\users\views.py changed, reloading.
INFO 2021-06-12 18:24:22,668 autoreload 636 Watching for file changes with StatReloader
INFO 2021-06-12 18:24:46,840 autoreload 636 Watching for file changes with StatReloader
INFO 2021-06-12 18:24:57,758 autoreload 250 F:\Python\Python_Project\python_test_developer\users\views.py changed, reloading.
INFO 2021-06-12 18:25:46,339 autoreload 636 Watching for file changes with StatReloader
INFO 2021-06-12 18:33:49,170 autoreload 636 Watching for file changes with StatReloader
ERROR 2021-06-12 18:33:59,179 log 224 Internal Server Error: /user/register/
Traceback (most recent call last):
  File "F:\Python\Python_Venv\Django_AutoTest\lib\site-packages\django\core\handlers\exception.py", line 47, in inner
    response = get_response(request)
  File "F:\Python\Python_Venv\Django_AutoTest\lib\site-packages\django\core\handlers\base.py", line 181, in _get_response
    response = wrapped_callback(request, *callback_args, **callback_kwargs)
  File "F:\Python\Python_Venv\Django_AutoTest\lib\site-packages\django\views\decorators\csrf.py", line 54, in wrapped_view
    return view_func(*args, **kwargs)
  File "F:\Python\Python_Venv\Django_AutoTest\lib\site-packages\rest_framework\viewsets.py", line 125, in view
    return self.dispatch(request, *args, **kwargs)
  File "F:\Python\Python_Venv\Django_AutoTest\lib\site-packages\rest_framework\views.py", line 509, in dispatch
    response = self.handle_exception(exc)
  File "F:\Python\Python_Venv\Django_AutoTest\lib\site-packages\rest_framework\views.py", line 469, in handle_exception
    self.raise_uncaught_exception(exc)
  File "F:\Python\Python_Venv\Django_AutoTest\lib\site-packages\rest_framework\views.py", line 480, in raise_uncaught_exception
    raise exc
  File "F:\Python\Python_Venv\Django_AutoTest\lib\site-packages\rest_framework\views.py", line 506, in dispatch
    response = handler(request, *args, **kwargs)
  File "F:\Python\Python_Project\python_test_developer\users\views.py", line 19, in create
    serializer.is_valid(raise_exception=True)
  File "F:\Python\Python_Venv\Django_AutoTest\lib\site-packages\rest_framework\serializers.py", line 220, in is_valid
    self._validated_data = self.run_validation(self.initial_data)
  File "F:\Python\Python_Venv\Django_AutoTest\lib\site-packages\rest_framework\serializers.py", line 419, in run_validation
    value = self.to_internal_value(data)
  File "F:\Python\Python_Venv\Django_AutoTest\lib\site-packages\rest_framework\serializers.py", line 476, in to_internal_value
    validated_value = field.run_validation(primitive_value)
  File "F:\Python\Python_Venv\Django_AutoTest\lib\site-packages\rest_framework\fields.py", line 799, in run_validation
    return super().run_validation(data)
  File "F:\Python\Python_Venv\Django_AutoTest\lib\site-packages\rest_framework\fields.py", line 569, in run_validation
    self.run_validators(value)
  File "F:\Python\Python_Venv\Django_AutoTest\lib\site-packages\rest_framework\fields.py", line 593, in run_validators
    validator(value)
TypeError: validate_password_check() missing 1 required positional argument: 'attr'
ERROR 2021-06-12 18:33:59,190 basehttp 161 "POST /user/register/ HTTP/1.1" 500 134426
INFO 2021-06-12 18:37:10,050 autoreload 250 F:\Python\Python_Project\python_test_developer\users\serializers.py changed, reloading.
INFO 2021-06-12 18:37:12,498 autoreload 636 Watching for file changes with StatReloader
ERROR 2021-06-12 18:37:14,753 log 224 Internal Server Error: /user/register/
Traceback (most recent call last):
  File "F:\Python\Python_Venv\Django_AutoTest\lib\site-packages\django\core\handlers\exception.py", line 47, in inner
    response = get_response(request)
  File "F:\Python\Python_Venv\Django_AutoTest\lib\site-packages\django\core\handlers\base.py", line 181, in _get_response
    response = wrapped_callback(request, *callback_args, **callback_kwargs)
  File "F:\Python\Python_Venv\Django_AutoTest\lib\site-packages\django\views\decorators\csrf.py", line 54, in wrapped_view
    return view_func(*args, **kwargs)
  File "F:\Python\Python_Venv\Django_AutoTest\lib\site-packages\rest_framework\viewsets.py", line 125, in view
    return self.dispatch(request, *args, **kwargs)
  File "F:\Python\Python_Venv\Django_AutoTest\lib\site-packages\rest_framework\views.py", line 509, in dispatch
    response = self.handle_exception(exc)
  File "F:\Python\Python_Venv\Django_AutoTest\lib\site-packages\rest_framework\views.py", line 469, in handle_exception
    self.raise_uncaught_exception(exc)
  File "F:\Python\Python_Venv\Django_AutoTest\lib\site-packages\rest_framework\views.py", line 480, in raise_uncaught_exception
    raise exc
  File "F:\Python\Python_Venv\Django_AutoTest\lib\site-packages\rest_framework\views.py", line 506, in dispatch
    response = handler(request, *args, **kwargs)
  File "F:\Python\Python_Project\python_test_developer\users\views.py", line 19, in create
    serializer.is_valid(raise_exception=True)
  File "F:\Python\Python_Venv\Django_AutoTest\lib\site-packages\rest_framework\serializers.py", line 220, in is_valid
    self._validated_data = self.run_validation(self.initial_data)
  File "F:\Python\Python_Venv\Django_AutoTest\lib\site-packages\rest_framework\serializers.py", line 419, in run_validation
    value = self.to_internal_value(data)
  File "F:\Python\Python_Venv\Django_AutoTest\lib\site-packages\rest_framework\serializers.py", line 476, in to_internal_value
    validated_value = field.run_validation(primitive_value)
  File "F:\Python\Python_Venv\Django_AutoTest\lib\site-packages\rest_framework\fields.py", line 799, in run_validation
    return super().run_validation(data)
  File "F:\Python\Python_Venv\Django_AutoTest\lib\site-packages\rest_framework\fields.py", line 569, in run_validation
    self.run_validators(value)
  File "F:\Python\Python_Venv\Django_AutoTest\lib\site-packages\rest_framework\fields.py", line 593, in run_validators
    validator(value)
TypeError: validate_password_check() missing 1 required positional argument: 'attr'
ERROR 2021-06-12 18:37:14,764 basehttp 161 "POST /user/register/ HTTP/1.1" 500 134426
INFO 2021-06-12 18:37:26,424 autoreload 250 F:\Python\Python_Project\python_test_developer\users\serializers.py changed, reloading.
INFO 2021-06-12 18:37:28,857 autoreload 636 Watching for file changes with StatReloader
INFO 2021-06-12 18:38:18,909 autoreload 636 Watching for file changes with StatReloader
ERROR 2021-06-12 18:38:23,841 log 224 Internal Server Error: /user/register/
Traceback (most recent call last):
  File "F:\Python\Python_Venv\Django_AutoTest\lib\site-packages\django\core\handlers\exception.py", line 47, in inner
    response = get_response(request)
  File "F:\Python\Python_Venv\Django_AutoTest\lib\site-packages\django\core\handlers\base.py", line 181, in _get_response
    response = wrapped_callback(request, *callback_args, **callback_kwargs)
  File "F:\Python\Python_Venv\Django_AutoTest\lib\site-packages\django\views\decorators\csrf.py", line 54, in wrapped_view
    return view_func(*args, **kwargs)
  File "F:\Python\Python_Venv\Django_AutoTest\lib\site-packages\rest_framework\viewsets.py", line 125, in view
    return self.dispatch(request, *args, **kwargs)
  File "F:\Python\Python_Venv\Django_AutoTest\lib\site-packages\rest_framework\views.py", line 509, in dispatch
    response = self.handle_exception(exc)
  File "F:\Python\Python_Venv\Django_AutoTest\lib\site-packages\rest_framework\views.py", line 469, in handle_exception
    self.raise_uncaught_exception(exc)
  File "F:\Python\Python_Venv\Django_AutoTest\lib\site-packages\rest_framework\views.py", line 480, in raise_uncaught_exception
    raise exc
  File "F:\Python\Python_Venv\Django_AutoTest\lib\site-packages\rest_framework\views.py", line 506, in dispatch
    response = handler(request, *args, **kwargs)
  File "F:\Python\Python_Project\python_test_developer\users\views.py", line 19, in create
    serializer.is_valid(raise_exception=True)
  File "F:\Python\Python_Venv\Django_AutoTest\lib\site-packages\rest_framework\serializers.py", line 220, in is_valid
    self._validated_data = self.run_validation(self.initial_data)
  File "F:\Python\Python_Venv\Django_AutoTest\lib\site-packages\rest_framework\serializers.py", line 422, in run_validation
    value = self.validate(value)
TypeError: validate() takes 1 positional argument but 2 were given
ERROR 2021-06-12 18:38:23,849 basehttp 161 "POST /user/register/ HTTP/1.1" 500 113445
INFO 2021-06-12 18:38:30,640 autoreload 250 F:\Python\Python_Project\python_test_developer\users\serializers.py changed, reloading.
INFO 2021-06-12 18:38:33,000 autoreload 636 Watching for file changes with StatReloader
ERROR 2021-06-12 18:38:47,716 log 224 Internal Server Error: /user/register/
Traceback (most recent call last):
  File "F:\Python\Python_Venv\Django_AutoTest\lib\site-packages\django\core\handlers\exception.py", line 47, in inner
    response = get_response(request)
  File "F:\Python\Python_Venv\Django_AutoTest\lib\site-packages\django\core\handlers\base.py", line 181, in _get_response
    response = wrapped_callback(request, *callback_args, **callback_kwargs)
  File "F:\Python\Python_Venv\Django_AutoTest\lib\site-packages\django\views\decorators\csrf.py", line 54, in wrapped_view
    return view_func(*args, **kwargs)
  File "F:\Python\Python_Venv\Django_AutoTest\lib\site-packages\rest_framework\viewsets.py", line 125, in view
    return self.dispatch(request, *args, **kwargs)
  File "F:\Python\Python_Venv\Django_AutoTest\lib\site-packages\rest_framework\views.py", line 511, in dispatch
    self.response = self.finalize_response(request, response, *args, **kwargs)
  File "F:\Python\Python_Venv\Django_AutoTest\lib\site-packages\rest_framework\views.py", line 423, in finalize_response
    assert isinstance(response, HttpResponseBase), (
AssertionError: Expected a `Response`, `HttpResponse` or `HttpStreamingResponse` to be returned from the view, but received a `<class 'NoneType'>`
ERROR 2021-06-12 18:38:47,728 basehttp 161 "POST /user/register/ HTTP/1.1" 500 84860
INFO 2021-06-12 18:39:43,448 autoreload 250 F:\Python\Python_Project\python_test_developer\users\serializers.py changed, reloading.
INFO 2021-06-12 18:39:45,805 autoreload 636 Watching for file changes with StatReloader
INFO 2021-06-12 18:39:48,593 autoreload 250 F:\Python\Python_Project\python_test_developer\users\serializers.py changed, reloading.
INFO 2021-06-12 18:39:50,973 autoreload 636 Watching for file changes with StatReloader
INFO 2021-06-12 18:39:54,902 autoreload 250 F:\Python\Python_Project\python_test_developer\users\serializers.py changed, reloading.
INFO 2021-06-12 18:39:57,095 autoreload 636 Watching for file changes with StatReloader
INFO 2021-06-12 18:39:59,884 autoreload 250 F:\Python\Python_Project\python_test_developer\users\serializers.py changed, reloading.
INFO 2021-06-12 18:40:15,768 autoreload 636 Watching for file changes with StatReloader
ERROR 2021-06-12 18:40:19,773 log 224 Internal Server Error: /user/register/
Traceback (most recent call last):
  File "F:\Python\Python_Venv\Django_AutoTest\lib\site-packages\django\core\handlers\exception.py", line 47, in inner
    response = get_response(request)
  File "F:\Python\Python_Venv\Django_AutoTest\lib\site-packages\django\core\handlers\base.py", line 181, in _get_response
    response = wrapped_callback(request, *callback_args, **callback_kwargs)
  File "F:\Python\Python_Venv\Django_AutoTest\lib\site-packages\django\views\decorators\csrf.py", line 54, in wrapped_view
    return view_func(*args, **kwargs)
  File "F:\Python\Python_Venv\Django_AutoTest\lib\site-packages\rest_framework\viewsets.py", line 125, in view
    return self.dispatch(request, *args, **kwargs)
  File "F:\Python\Python_Venv\Django_AutoTest\lib\site-packages\rest_framework\views.py", line 509, in dispatch
    response = self.handle_exception(exc)
  File "F:\Python\Python_Venv\Django_AutoTest\lib\site-packages\rest_framework\views.py", line 469, in handle_exception
    self.raise_uncaught_exception(exc)
  File "F:\Python\Python_Venv\Django_AutoTest\lib\site-packages\rest_framework\views.py", line 480, in raise_uncaught_exception
    raise exc
  File "F:\Python\Python_Venv\Django_AutoTest\lib\site-packages\rest_framework\views.py", line 506, in dispatch
    response = handler(request, *args, **kwargs)
  File "F:\Python\Python_Project\python_test_developer\users\views.py", line 19, in create
    serializer.is_valid(raise_exception=True)
  File "F:\Python\Python_Venv\Django_AutoTest\lib\site-packages\rest_framework\serializers.py", line 220, in is_valid
    self._validated_data = self.run_validation(self.initial_data)
  File "F:\Python\Python_Venv\Django_AutoTest\lib\site-packages\rest_framework\serializers.py", line 419, in run_validation
    value = self.to_internal_value(data)
  File "F:\Python\Python_Venv\Django_AutoTest\lib\site-packages\rest_framework\serializers.py", line 476, in to_internal_value
    validated_value = field.run_validation(primitive_value)
  File "F:\Python\Python_Venv\Django_AutoTest\lib\site-packages\rest_framework\fields.py", line 799, in run_validation
    return super().run_validation(data)
  File "F:\Python\Python_Venv\Django_AutoTest\lib\site-packages\rest_framework\fields.py", line 569, in run_validation
    self.run_validators(value)
  File "F:\Python\Python_Venv\Django_AutoTest\lib\site-packages\rest_framework\fields.py", line 593, in run_validators
    validator(value)
TypeError: validate_xxx() missing 1 required positional argument: 'attr'
ERROR 2021-06-12 18:40:19,785 basehttp 161 "POST /user/register/ HTTP/1.1" 500 134261
INFO 2021-06-12 18:40:50,904 autoreload 250 F:\Python\Python_Project\python_test_developer\users\serializers.py changed, reloading.
INFO 2021-06-12 18:40:53,284 autoreload 636 Watching for file changes with StatReloader
ERROR 2021-06-12 18:40:57,530 log 224 Internal Server Error: /user/register/
Traceback (most recent call last):
  File "F:\Python\Python_Venv\Django_AutoTest\lib\site-packages\django\core\handlers\exception.py", line 47, in inner
    response = get_response(request)
  File "F:\Python\Python_Venv\Django_AutoTest\lib\site-packages\django\core\handlers\base.py", line 181, in _get_response
    response = wrapped_callback(request, *callback_args, **callback_kwargs)
  File "F:\Python\Python_Venv\Django_AutoTest\lib\site-packages\django\views\decorators\csrf.py", line 54, in wrapped_view
    return view_func(*args, **kwargs)
  File "F:\Python\Python_Venv\Django_AutoTest\lib\site-packages\rest_framework\viewsets.py", line 125, in view
    return self.dispatch(request, *args, **kwargs)
  File "F:\Python\Python_Venv\Django_AutoTest\lib\site-packages\rest_framework\views.py", line 509, in dispatch
    response = self.handle_exception(exc)
  File "F:\Python\Python_Venv\Django_AutoTest\lib\site-packages\rest_framework\views.py", line 469, in handle_exception
    self.raise_uncaught_exception(exc)
  File "F:\Python\Python_Venv\Django_AutoTest\lib\site-packages\rest_framework\views.py", line 480, in raise_uncaught_exception
    raise exc
  File "F:\Python\Python_Venv\Django_AutoTest\lib\site-packages\rest_framework\views.py", line 506, in dispatch
    response = handler(request, *args, **kwargs)
  File "F:\Python\Python_Project\python_test_developer\users\views.py", line 19, in create
    serializer.is_valid(raise_exception=True)
  File "F:\Python\Python_Venv\Django_AutoTest\lib\site-packages\rest_framework\serializers.py", line 220, in is_valid
    self._validated_data = self.run_validation(self.initial_data)
  File "F:\Python\Python_Venv\Django_AutoTest\lib\site-packages\rest_framework\serializers.py", line 419, in run_validation
    value = self.to_internal_value(data)
  File "F:\Python\Python_Venv\Django_AutoTest\lib\site-packages\rest_framework\serializers.py", line 476, in to_internal_value
    validated_value = field.run_validation(primitive_value)
  File "F:\Python\Python_Venv\Django_AutoTest\lib\site-packages\rest_framework\fields.py", line 799, in run_validation
    return super().run_validation(data)
  File "F:\Python\Python_Venv\Django_AutoTest\lib\site-packages\rest_framework\fields.py", line 569, in run_validation
    self.run_validators(value)
  File "F:\Python\Python_Venv\Django_AutoTest\lib\site-packages\rest_framework\fields.py", line 593, in run_validators
    validator(value)
TypeError: validate_function() missing 1 required positional argument: 'attr'
ERROR 2021-06-12 18:40:57,542 basehttp 161 "POST /user/register/ HTTP/1.1" 500 134336
INFO 2021-06-12 18:41:45,557 autoreload 250 F:\Python\Python_Project\python_test_developer\users\serializers.py changed, reloading.
INFO 2021-06-12 18:41:48,040 autoreload 636 Watching for file changes with StatReloader
INFO 2021-06-12 18:41:50,836 autoreload 250 F:\Python\Python_Project\python_test_developer\users\serializers.py changed, reloading.
INFO 2021-06-12 18:41:53,267 autoreload 636 Watching for file changes with StatReloader
INFO 2021-06-12 18:41:56,173 autoreload 250 F:\Python\Python_Project\python_test_developer\users\serializers.py changed, reloading.
INFO 2021-06-12 18:41:58,447 autoreload 636 Watching for file changes with StatReloader
ERROR 2021-06-12 18:42:00,411 log 224 Internal Server Error: /user/register/
Traceback (most recent call last):
  File "F:\Python\Python_Venv\Django_AutoTest\lib\site-packages\django\core\handlers\exception.py", line 47, in inner
    response = get_response(request)
  File "F:\Python\Python_Venv\Django_AutoTest\lib\site-packages\django\core\handlers\base.py", line 181, in _get_response
    response = wrapped_callback(request, *callback_args, **callback_kwargs)
  File "F:\Python\Python_Venv\Django_AutoTest\lib\site-packages\django\views\decorators\csrf.py", line 54, in wrapped_view
    return view_func(*args, **kwargs)
  File "F:\Python\Python_Venv\Django_AutoTest\lib\site-packages\rest_framework\viewsets.py", line 125, in view
    return self.dispatch(request, *args, **kwargs)
  File "F:\Python\Python_Venv\Django_AutoTest\lib\site-packages\rest_framework\views.py", line 509, in dispatch
    response = self.handle_exception(exc)
  File "F:\Python\Python_Venv\Django_AutoTest\lib\site-packages\rest_framework\views.py", line 469, in handle_exception
    self.raise_uncaught_exception(exc)
  File "F:\Python\Python_Venv\Django_AutoTest\lib\site-packages\rest_framework\views.py", line 480, in raise_uncaught_exception
    raise exc
  File "F:\Python\Python_Venv\Django_AutoTest\lib\site-packages\rest_framework\views.py", line 506, in dispatch
    response = handler(request, *args, **kwargs)
  File "F:\Python\Python_Project\python_test_developer\users\views.py", line 19, in create
    serializer.is_valid(raise_exception=True)
  File "F:\Python\Python_Venv\Django_AutoTest\lib\site-packages\rest_framework\serializers.py", line 220, in is_valid
    self._validated_data = self.run_validation(self.initial_data)
  File "F:\Python\Python_Venv\Django_AutoTest\lib\site-packages\rest_framework\serializers.py", line 419, in run_validation
    value = self.to_internal_value(data)
  File "F:\Python\Python_Venv\Django_AutoTest\lib\site-packages\rest_framework\serializers.py", line 476, in to_internal_value
    validated_value = field.run_validation(primitive_value)
  File "F:\Python\Python_Venv\Django_AutoTest\lib\site-packages\rest_framework\fields.py", line 799, in run_validation
    return super().run_validation(data)
  File "F:\Python\Python_Venv\Django_AutoTest\lib\site-packages\rest_framework\fields.py", line 569, in run_validation
    self.run_validators(value)
  File "F:\Python\Python_Venv\Django_AutoTest\lib\site-packages\rest_framework\fields.py", line 593, in run_validators
    validator(value)
TypeError: validate_function() missing 1 required positional argument: 'attr'
ERROR 2021-06-12 18:42:00,422 basehttp 161 "POST /user/register/ HTTP/1.1" 500 134336
INFO 2021-06-12 18:44:27,391 autoreload 250 F:\Python\Python_Project\python_test_developer\users\serializers.py changed, reloading.
INFO 2021-06-12 18:46:12,824 autoreload 636 Watching for file changes with StatReloader
ERROR 2021-06-12 18:46:15,889 log 224 Internal Server Error: /user/register/
Traceback (most recent call last):
  File "F:\Python\Python_Venv\Django_AutoTest\lib\site-packages\django\core\handlers\exception.py", line 47, in inner
    response = get_response(request)
  File "F:\Python\Python_Venv\Django_AutoTest\lib\site-packages\django\core\handlers\base.py", line 181, in _get_response
    response = wrapped_callback(request, *callback_args, **callback_kwargs)
  File "F:\Python\Python_Venv\Django_AutoTest\lib\site-packages\django\views\decorators\csrf.py", line 54, in wrapped_view
    return view_func(*args, **kwargs)
  File "F:\Python\Python_Venv\Django_AutoTest\lib\site-packages\rest_framework\viewsets.py", line 125, in view
    return self.dispatch(request, *args, **kwargs)
  File "F:\Python\Python_Venv\Django_AutoTest\lib\site-packages\rest_framework\views.py", line 509, in dispatch
    response = self.handle_exception(exc)
  File "F:\Python\Python_Venv\Django_AutoTest\lib\site-packages\rest_framework\views.py", line 469, in handle_exception
    self.raise_uncaught_exception(exc)
  File "F:\Python\Python_Venv\Django_AutoTest\lib\site-packages\rest_framework\views.py", line 480, in raise_uncaught_exception
    raise exc
  File "F:\Python\Python_Venv\Django_AutoTest\lib\site-packages\rest_framework\views.py", line 506, in dispatch
    response = handler(request, *args, **kwargs)
  File "F:\Python\Python_Project\python_test_developer\users\views.py", line 19, in create
    serializer.is_valid(raise_exception=True)
  File "F:\Python\Python_Venv\Django_AutoTest\lib\site-packages\rest_framework\serializers.py", line 220, in is_valid
    self._validated_data = self.run_validation(self.initial_data)
  File "F:\Python\Python_Venv\Django_AutoTest\lib\site-packages\rest_framework\serializers.py", line 419, in run_validation
    value = self.to_internal_value(data)
  File "F:\Python\Python_Venv\Django_AutoTest\lib\site-packages\rest_framework\serializers.py", line 476, in to_internal_value
    validated_value = field.run_validation(primitive_value)
  File "F:\Python\Python_Venv\Django_AutoTest\lib\site-packages\rest_framework\fields.py", line 799, in run_validation
    return super().run_validation(data)
  File "F:\Python\Python_Venv\Django_AutoTest\lib\site-packages\rest_framework\fields.py", line 569, in run_validation
    self.run_validators(value)
  File "F:\Python\Python_Venv\Django_AutoTest\lib\site-packages\rest_framework\fields.py", line 593, in run_validators
    validator(value)
TypeError: validate_password_confirm() missing 1 required positional argument: 'attr'
ERROR 2021-06-12 18:46:15,901 basehttp 161 "POST /user/register/ HTTP/1.1" 500 136951
INFO 2021-06-12 18:49:07,713 autoreload 250 F:\Python\Python_Project\python_test_developer\users\serializers.py changed, reloading.
INFO 2021-06-12 18:49:09,999 autoreload 636 Watching for file changes with StatReloader
INFO 2021-06-12 18:50:30,851 autoreload 636 Watching for file changes with StatReloader
ERROR 2021-06-12 18:50:35,727 log 224 Internal Server Error: /user/register/
Traceback (most recent call last):
  File "F:\Python\Python_Venv\Django_AutoTest\lib\site-packages\django\core\handlers\exception.py", line 47, in inner
    response = get_response(request)
  File "F:\Python\Python_Venv\Django_AutoTest\lib\site-packages\django\core\handlers\base.py", line 181, in _get_response
    response = wrapped_callback(request, *callback_args, **callback_kwargs)
  File "F:\Python\Python_Venv\Django_AutoTest\lib\site-packages\django\views\decorators\csrf.py", line 54, in wrapped_view
    return view_func(*args, **kwargs)
  File "F:\Python\Python_Venv\Django_AutoTest\lib\site-packages\rest_framework\viewsets.py", line 125, in view
    return self.dispatch(request, *args, **kwargs)
  File "F:\Python\Python_Venv\Django_AutoTest\lib\site-packages\rest_framework\views.py", line 509, in dispatch
    response = self.handle_exception(exc)
  File "F:\Python\Python_Venv\Django_AutoTest\lib\site-packages\rest_framework\views.py", line 469, in handle_exception
    self.raise_uncaught_exception(exc)
  File "F:\Python\Python_Venv\Django_AutoTest\lib\site-packages\rest_framework\views.py", line 480, in raise_uncaught_exception
    raise exc
  File "F:\Python\Python_Venv\Django_AutoTest\lib\site-packages\rest_framework\views.py", line 506, in dispatch
    response = handler(request, *args, **kwargs)
  File "F:\Python\Python_Project\python_test_developer\users\views.py", line 20, in create
    username = serializer.data['username']
  File "F:\Python\Python_Venv\Django_AutoTest\lib\site-packages\rest_framework\serializers.py", line 548, in data
    ret = super().data
  File "F:\Python\Python_Venv\Django_AutoTest\lib\site-packages\rest_framework\serializers.py", line 248, in data
    self._data = self.to_representation(self.validated_data)
  File "F:\Python\Python_Venv\Django_AutoTest\lib\site-packages\rest_framework\serializers.py", line 502, in to_representation
    attribute = field.get_attribute(instance)
  File "F:\Python\Python_Venv\Django_AutoTest\lib\site-packages\rest_framework\relations.py", line 538, in get_attribute
    relationship = get_attribute(instance, self.source_attrs)
  File "F:\Python\Python_Venv\Django_AutoTest\lib\site-packages\rest_framework\fields.py", line 95, in get_attribute
    instance = instance[attr]
KeyError: 'groups'
ERROR 2021-06-12 18:50:35,743 basehttp 161 "POST /user/register/ HTTP/1.1" 500 128925
INFO 2021-06-12 18:51:41,821 autoreload 250 F:\Python\Python_Project\python_test_developer\users\views.py changed, reloading.
ERROR 2021-06-12 18:51:48,130 log 224 Internal Server Error: /user/register/
Traceback (most recent call last):
  File "F:\Python\Python_Venv\Django_AutoTest\lib\site-packages\django\core\handlers\exception.py", line 47, in inner
    response = get_response(request)
  File "F:\Python\Python_Venv\Django_AutoTest\lib\site-packages\django\core\handlers\base.py", line 181, in _get_response
    response = wrapped_callback(request, *callback_args, **callback_kwargs)
  File "F:\Python\Python_Venv\Django_AutoTest\lib\site-packages\django\views\decorators\csrf.py", line 54, in wrapped_view
    return view_func(*args, **kwargs)
  File "F:\Python\Python_Venv\Django_AutoTest\lib\site-packages\rest_framework\viewsets.py", line 125, in view
    return self.dispatch(request, *args, **kwargs)
  File "F:\Python\Python_Venv\Django_AutoTest\lib\site-packages\rest_framework\views.py", line 509, in dispatch
    response = self.handle_exception(exc)
  File "F:\Python\Python_Venv\Django_AutoTest\lib\site-packages\rest_framework\views.py", line 469, in handle_exception
    self.raise_uncaught_exception(exc)
  File "F:\Python\Python_Venv\Django_AutoTest\lib\site-packages\rest_framework\views.py", line 480, in raise_uncaught_exception
    raise exc
  File "F:\Python\Python_Venv\Django_AutoTest\lib\site-packages\rest_framework\views.py", line 506, in dispatch
    response = handler(request, *args, **kwargs)
  File "F:\Python\Python_Project\python_test_developer\users\views.py", line 20, in create
    username = serializer.data
  File "F:\Python\Python_Venv\Django_AutoTest\lib\site-packages\rest_framework\serializers.py", line 548, in data
    ret = super().data
  File "F:\Python\Python_Venv\Django_AutoTest\lib\site-packages\rest_framework\serializers.py", line 248, in data
    self._data = self.to_representation(self.validated_data)
  File "F:\Python\Python_Venv\Django_AutoTest\lib\site-packages\rest_framework\serializers.py", line 502, in to_representation
    attribute = field.get_attribute(instance)
  File "F:\Python\Python_Venv\Django_AutoTest\lib\site-packages\rest_framework\relations.py", line 538, in get_attribute
    relationship = get_attribute(instance, self.source_attrs)
  File "F:\Python\Python_Venv\Django_AutoTest\lib\site-packages\rest_framework\fields.py", line 95, in get_attribute
    instance = instance[attr]
KeyError: 'groups'
ERROR 2021-06-12 18:51:48,142 basehttp 161 "POST /user/register/ HTTP/1.1" 500 128688
INFO 2021-06-12 18:52:09,338 autoreload 636 Watching for file changes with StatReloader
ERROR 2021-06-12 18:52:13,567 log 224 Internal Server Error: /user/register/
Traceback (most recent call last):
  File "F:\Python\Python_Venv\Django_AutoTest\lib\site-packages\django\core\handlers\exception.py", line 47, in inner
    response = get_response(request)
  File "F:\Python\Python_Venv\Django_AutoTest\lib\site-packages\django\core\handlers\base.py", line 181, in _get_response
    response = wrapped_callback(request, *callback_args, **callback_kwargs)
  File "F:\Python\Python_Venv\Django_AutoTest\lib\site-packages\django\views\decorators\csrf.py", line 54, in wrapped_view
    return view_func(*args, **kwargs)
  File "F:\Python\Python_Venv\Django_AutoTest\lib\site-packages\rest_framework\viewsets.py", line 125, in view
    return self.dispatch(request, *args, **kwargs)
  File "F:\Python\Python_Venv\Django_AutoTest\lib\site-packages\rest_framework\views.py", line 509, in dispatch
    response = self.handle_exception(exc)
  File "F:\Python\Python_Venv\Django_AutoTest\lib\site-packages\rest_framework\views.py", line 469, in handle_exception
    self.raise_uncaught_exception(exc)
  File "F:\Python\Python_Venv\Django_AutoTest\lib\site-packages\rest_framework\views.py", line 480, in raise_uncaught_exception
    raise exc
  File "F:\Python\Python_Venv\Django_AutoTest\lib\site-packages\rest_framework\views.py", line 506, in dispatch
    response = handler(request, *args, **kwargs)
  File "F:\Python\Python_Project\python_test_developer\users\views.py", line 20, in create
    username = serializer.data
  File "F:\Python\Python_Venv\Django_AutoTest\lib\site-packages\rest_framework\serializers.py", line 548, in data
    ret = super().data
  File "F:\Python\Python_Venv\Django_AutoTest\lib\site-packages\rest_framework\serializers.py", line 248, in data
    self._data = self.to_representation(self.validated_data)
  File "F:\Python\Python_Venv\Django_AutoTest\lib\site-packages\rest_framework\serializers.py", line 502, in to_representation
    attribute = field.get_attribute(instance)
  File "F:\Python\Python_Venv\Django_AutoTest\lib\site-packages\rest_framework\relations.py", line 538, in get_attribute
    relationship = get_attribute(instance, self.source_attrs)
  File "F:\Python\Python_Venv\Django_AutoTest\lib\site-packages\rest_framework\fields.py", line 95, in get_attribute
    instance = instance[attr]
KeyError: 'groups'
ERROR 2021-06-12 18:52:13,584 basehttp 161 "POST /user/register/ HTTP/1.1" 500 128881
INFO 2021-06-12 18:54:16,845 autoreload 250 F:\Python\Python_Project\python_test_developer\users\views.py changed, reloading.
INFO 2021-06-12 18:54:19,278 autoreload 636 Watching for file changes with StatReloader
INFO 2021-06-12 18:55:33,593 autoreload 250 F:\Python\Python_Project\python_test_developer\users\views.py changed, reloading.
INFO 2021-06-12 18:55:42,917 autoreload 636 Watching for file changes with StatReloader
ERROR 2021-06-12 18:55:51,001 log 224 Internal Server Error: /user/register/
Traceback (most recent call last):
  File "F:\Python\Python_Venv\Django_AutoTest\lib\site-packages\django\core\handlers\exception.py", line 47, in inner
    response = get_response(request)
  File "F:\Python\Python_Venv\Django_AutoTest\lib\site-packages\django\core\handlers\base.py", line 181, in _get_response
    response = wrapped_callback(request, *callback_args, **callback_kwargs)
  File "F:\Python\Python_Venv\Django_AutoTest\lib\site-packages\django\views\decorators\csrf.py", line 54, in wrapped_view
    return view_func(*args, **kwargs)
  File "F:\Python\Python_Venv\Django_AutoTest\lib\site-packages\rest_framework\viewsets.py", line 125, in view
    return self.dispatch(request, *args, **kwargs)
  File "F:\Python\Python_Venv\Django_AutoTest\lib\site-packages\rest_framework\views.py", line 509, in dispatch
    response = self.handle_exception(exc)
  File "F:\Python\Python_Venv\Django_AutoTest\lib\site-packages\rest_framework\views.py", line 469, in handle_exception
    self.raise_uncaught_exception(exc)
  File "F:\Python\Python_Venv\Django_AutoTest\lib\site-packages\rest_framework\views.py", line 480, in raise_uncaught_exception
    raise exc
  File "F:\Python\Python_Venv\Django_AutoTest\lib\site-packages\rest_framework\views.py", line 506, in dispatch
    response = handler(request, *args, **kwargs)
  File "F:\Python\Python_Project\python_test_developer\users\views.py", line 21, in create
    password = serializer.data
  File "F:\Python\Python_Venv\Django_AutoTest\lib\site-packages\rest_framework\serializers.py", line 548, in data
    ret = super().data
  File "F:\Python\Python_Venv\Django_AutoTest\lib\site-packages\rest_framework\serializers.py", line 248, in data
    self._data = self.to_representation(self.validated_data)
  File "F:\Python\Python_Venv\Django_AutoTest\lib\site-packages\rest_framework\serializers.py", line 502, in to_representation
    attribute = field.get_attribute(instance)
  File "F:\Python\Python_Venv\Django_AutoTest\lib\site-packages\rest_framework\relations.py", line 538, in get_attribute
    relationship = get_attribute(instance, self.source_attrs)
  File "F:\Python\Python_Venv\Django_AutoTest\lib\site-packages\rest_framework\fields.py", line 95, in get_attribute
    instance = instance[attr]
KeyError: 'groups'
ERROR 2021-06-12 18:55:51,022 basehttp 161 "POST /user/register/ HTTP/1.1" 500 129681
INFO 2021-06-12 18:57:11,625 autoreload 636 Watching for file changes with StatReloader
ERROR 2021-06-12 18:57:17,039 log 224 Internal Server Error: /user/register/
Traceback (most recent call last):
  File "F:\Python\Python_Venv\Django_AutoTest\lib\site-packages\django\core\handlers\exception.py", line 47, in inner
    response = get_response(request)
  File "F:\Python\Python_Venv\Django_AutoTest\lib\site-packages\django\core\handlers\base.py", line 181, in _get_response
    response = wrapped_callback(request, *callback_args, **callback_kwargs)
  File "F:\Python\Python_Venv\Django_AutoTest\lib\site-packages\django\views\decorators\csrf.py", line 54, in wrapped_view
    return view_func(*args, **kwargs)
  File "F:\Python\Python_Venv\Django_AutoTest\lib\site-packages\rest_framework\viewsets.py", line 125, in view
    return self.dispatch(request, *args, **kwargs)
  File "F:\Python\Python_Venv\Django_AutoTest\lib\site-packages\rest_framework\views.py", line 509, in dispatch
    response = self.handle_exception(exc)
  File "F:\Python\Python_Venv\Django_AutoTest\lib\site-packages\rest_framework\views.py", line 469, in handle_exception
    self.raise_uncaught_exception(exc)
  File "F:\Python\Python_Venv\Django_AutoTest\lib\site-packages\rest_framework\views.py", line 480, in raise_uncaught_exception
    raise exc
  File "F:\Python\Python_Venv\Django_AutoTest\lib\site-packages\rest_framework\views.py", line 506, in dispatch
    response = handler(request, *args, **kwargs)
  File "F:\Python\Python_Project\python_test_developer\users\views.py", line 21, in create
    password = serializer.data
  File "F:\Python\Python_Venv\Django_AutoTest\lib\site-packages\rest_framework\serializers.py", line 548, in data
    ret = super().data
  File "F:\Python\Python_Venv\Django_AutoTest\lib\site-packages\rest_framework\serializers.py", line 248, in data
    self._data = self.to_representation(self.validated_data)
  File "F:\Python\Python_Venv\Django_AutoTest\lib\site-packages\rest_framework\serializers.py", line 502, in to_representation
    attribute = field.get_attribute(instance)
  File "F:\Python\Python_Venv\Django_AutoTest\lib\site-packages\rest_framework\relations.py", line 538, in get_attribute
    relationship = get_attribute(instance, self.source_attrs)
  File "F:\Python\Python_Venv\Django_AutoTest\lib\site-packages\rest_framework\fields.py", line 95, in get_attribute
    instance = instance[attr]
KeyError: 'groups'
ERROR 2021-06-12 18:57:17,054 basehttp 161 "POST /user/register/ HTTP/1.1" 500 129681
INFO 2021-06-12 19:03:41,477 autoreload 250 F:\Python\Python_Project\python_test_developer\users\views.py changed, reloading.
INFO 2021-06-12 19:03:43,862 autoreload 636 Watching for file changes with StatReloader
INFO 2021-06-12 19:04:21,926 autoreload 636 Watching for file changes with StatReloader
ERROR 2021-06-12 19:04:45,825 log 224 Internal Server Error: /user/register/
Traceback (most recent call last):
  File "F:\Python\Python_Venv\Django_AutoTest\lib\site-packages\django\core\handlers\exception.py", line 47, in inner
    response = get_response(request)
  File "F:\Python\Python_Venv\Django_AutoTest\lib\site-packages\django\core\handlers\base.py", line 181, in _get_response
    response = wrapped_callback(request, *callback_args, **callback_kwargs)
  File "F:\Python\Python_Venv\Django_AutoTest\lib\site-packages\django\views\decorators\csrf.py", line 54, in wrapped_view
    return view_func(*args, **kwargs)
  File "F:\Python\Python_Venv\Django_AutoTest\lib\site-packages\rest_framework\viewsets.py", line 125, in view
    return self.dispatch(request, *args, **kwargs)
  File "F:\Python\Python_Venv\Django_AutoTest\lib\site-packages\rest_framework\views.py", line 509, in dispatch
    response = self.handle_exception(exc)
  File "F:\Python\Python_Venv\Django_AutoTest\lib\site-packages\rest_framework\views.py", line 469, in handle_exception
    self.raise_uncaught_exception(exc)
  File "F:\Python\Python_Venv\Django_AutoTest\lib\site-packages\rest_framework\views.py", line 480, in raise_uncaught_exception
    raise exc
  File "F:\Python\Python_Venv\Django_AutoTest\lib\site-packages\rest_framework\views.py", line 506, in dispatch
    response = handler(request, *args, **kwargs)
  File "F:\Python\Python_Project\python_test_developer\users\views.py", line 22, in create
    password = serializer.data
  File "F:\Python\Python_Venv\Django_AutoTest\lib\site-packages\rest_framework\serializers.py", line 548, in data
    ret = super().data
  File "F:\Python\Python_Venv\Django_AutoTest\lib\site-packages\rest_framework\serializers.py", line 246, in data
    self._data = self.to_representation(self.instance)
  File "F:\Python\Python_Venv\Django_AutoTest\lib\site-packages\rest_framework\serializers.py", line 502, in to_representation
    attribute = field.get_attribute(instance)
  File "F:\Python\Python_Venv\Django_AutoTest\lib\site-packages\rest_framework\relations.py", line 538, in get_attribute
    relationship = get_attribute(instance, self.source_attrs)
  File "F:\Python\Python_Venv\Django_AutoTest\lib\site-packages\rest_framework\fields.py", line 95, in get_attribute
    instance = instance[attr]
KeyError: 'groups'
ERROR 2021-06-12 19:04:45,841 basehttp 161 "POST /user/register/ HTTP/1.1" 500 132049
INFO 2021-06-12 19:05:02,841 autoreload 250 F:\Python\Python_Project\python_test_developer\users\views.py changed, reloading.
INFO 2021-06-12 19:05:05,276 autoreload 636 Watching for file changes with StatReloader
INFO 2021-06-12 19:05:53,404 autoreload 636 Watching for file changes with StatReloader
INFO 2021-06-12 19:05:56,273 autoreload 250 F:\Python\Python_Project\python_test_developer\users\views.py changed, reloading.
INFO 2021-06-12 19:05:58,610 autoreload 636 Watching for file changes with StatReloader
ERROR 2021-06-12 19:06:05,128 log 224 Internal Server Error: /user/register/
Traceback (most recent call last):
  File "F:\Python\Python_Venv\Django_AutoTest\lib\site-packages\django\core\handlers\exception.py", line 47, in inner
    response = get_response(request)
  File "F:\Python\Python_Venv\Django_AutoTest\lib\site-packages\django\core\handlers\base.py", line 181, in _get_response
    response = wrapped_callback(request, *callback_args, **callback_kwargs)
  File "F:\Python\Python_Venv\Django_AutoTest\lib\site-packages\django\views\decorators\csrf.py", line 54, in wrapped_view
    return view_func(*args, **kwargs)
  File "F:\Python\Python_Venv\Django_AutoTest\lib\site-packages\rest_framework\viewsets.py", line 125, in view
    return self.dispatch(request, *args, **kwargs)
  File "F:\Python\Python_Venv\Django_AutoTest\lib\site-packages\rest_framework\views.py", line 509, in dispatch
    response = self.handle_exception(exc)
  File "F:\Python\Python_Venv\Django_AutoTest\lib\site-packages\rest_framework\views.py", line 469, in handle_exception
    self.raise_uncaught_exception(exc)
  File "F:\Python\Python_Venv\Django_AutoTest\lib\site-packages\rest_framework\views.py", line 480, in raise_uncaught_exception
    raise exc
  File "F:\Python\Python_Venv\Django_AutoTest\lib\site-packages\rest_framework\views.py", line 506, in dispatch
    response = handler(request, *args, **kwargs)
  File "F:\Python\Python_Project\python_test_developer\users\views.py", line 22, in create
    password = serializer.data
  File "F:\Python\Python_Venv\Django_AutoTest\lib\site-packages\rest_framework\serializers.py", line 548, in data
    ret = super().data
  File "F:\Python\Python_Venv\Django_AutoTest\lib\site-packages\rest_framework\serializers.py", line 246, in data
    self._data = self.to_representation(self.instance)
  File "F:\Python\Python_Venv\Django_AutoTest\lib\site-packages\rest_framework\serializers.py", line 502, in to_representation
    attribute = field.get_attribute(instance)
  File "F:\Python\Python_Venv\Django_AutoTest\lib\site-packages\rest_framework\relations.py", line 538, in get_attribute
    relationship = get_attribute(instance, self.source_attrs)
  File "F:\Python\Python_Venv\Django_AutoTest\lib\site-packages\rest_framework\fields.py", line 95, in get_attribute
    instance = instance[attr]
KeyError: 'groups'
ERROR 2021-06-12 19:06:05,144 basehttp 161 "POST /user/register/ HTTP/1.1" 500 132338
INFO 2021-06-12 19:06:23,235 autoreload 250 F:\Python\Python_Project\python_test_developer\users\views.py changed, reloading.
INFO 2021-06-12 19:06:25,628 autoreload 636 Watching for file changes with StatReloader
INFO 2021-06-12 19:07:06,417 autoreload 250 F:\Python\Python_Project\python_test_developer\users\views.py changed, reloading.
INFO 2021-06-12 19:07:08,694 autoreload 636 Watching for file changes with StatReloader
INFO 2021-06-12 22:18:14,440 autoreload 636 Watching for file changes with StatReloader
INFO 2021-06-12 23:45:48,554 autoreload 636 Watching for file changes with StatReloader
ERROR 2021-06-12 23:46:58,898 log 224 Internal Server Error: /user/register/
Traceback (most recent call last):
  File "F:\Python\Python_Venv\Django_AutoTest\lib\site-packages\django\core\handlers\exception.py", line 47, in inner
    response = get_response(request)
  File "F:\Python\Python_Venv\Django_AutoTest\lib\site-packages\django\core\handlers\base.py", line 181, in _get_response
    response = wrapped_callback(request, *callback_args, **callback_kwargs)
  File "F:\Python\Python_Venv\Django_AutoTest\lib\site-packages\django\views\decorators\csrf.py", line 54, in wrapped_view
    return view_func(*args, **kwargs)
  File "F:\Python\Python_Venv\Django_AutoTest\lib\site-packages\rest_framework\viewsets.py", line 125, in view
    return self.dispatch(request, *args, **kwargs)
  File "F:\Python\Python_Venv\Django_AutoTest\lib\site-packages\rest_framework\views.py", line 509, in dispatch
    response = self.handle_exception(exc)
  File "F:\Python\Python_Venv\Django_AutoTest\lib\site-packages\rest_framework\views.py", line 469, in handle_exception
    self.raise_uncaught_exception(exc)
  File "F:\Python\Python_Venv\Django_AutoTest\lib\site-packages\rest_framework\views.py", line 480, in raise_uncaught_exception
    raise exc
  File "F:\Python\Python_Venv\Django_AutoTest\lib\site-packages\rest_framework\views.py", line 506, in dispatch
    response = handler(request, *args, **kwargs)
  File "F:\Python\Python_Project\python_test_developer\users\views.py", line 27, in create
    user = serializer.object.get('user') or request.user
AttributeError: 'UserRegisterModelSeralizer' object has no attribute 'object'
ERROR 2021-06-12 23:46:58,910 basehttp 161 "POST /user/register/ HTTP/1.1" 500 102106
INFO 2021-06-12 23:47:18,198 autoreload 250 F:\Python\Python_Project\python_test_developer\users\views.py changed, reloading.
INFO 2021-06-12 23:47:20,790 autoreload 636 Watching for file changes with StatReloader
WARNING 2021-06-12 23:47:28,130 log 224 Bad Request: /user/register/
WARNING 2021-06-12 23:47:28,132 basehttp 161 "POST /user/register/ HTTP/1.1" 400 59
ERROR 2021-06-12 23:48:17,567 log 224 Internal Server Error: /user/register/
Traceback (most recent call last):
  File "F:\Python\Python_Venv\Django_AutoTest\lib\site-packages\django\core\handlers\exception.py", line 47, in inner
    response = get_response(request)
  File "F:\Python\Python_Venv\Django_AutoTest\lib\site-packages\django\core\handlers\base.py", line 181, in _get_response
    response = wrapped_callback(request, *callback_args, **callback_kwargs)
  File "F:\Python\Python_Venv\Django_AutoTest\lib\site-packages\django\views\decorators\csrf.py", line 54, in wrapped_view
    return view_func(*args, **kwargs)
  File "F:\Python\Python_Venv\Django_AutoTest\lib\site-packages\rest_framework\viewsets.py", line 125, in view
    return self.dispatch(request, *args, **kwargs)
  File "F:\Python\Python_Venv\Django_AutoTest\lib\site-packages\rest_framework\views.py", line 509, in dispatch
    response = self.handle_exception(exc)
  File "F:\Python\Python_Venv\Django_AutoTest\lib\site-packages\rest_framework\views.py", line 469, in handle_exception
    self.raise_uncaught_exception(exc)
  File "F:\Python\Python_Venv\Django_AutoTest\lib\site-packages\rest_framework\views.py", line 480, in raise_uncaught_exception
    raise exc
  File "F:\Python\Python_Venv\Django_AutoTest\lib\site-packages\rest_framework\views.py", line 506, in dispatch
    response = handler(request, *args, **kwargs)
  File "F:\Python\Python_Project\python_test_developer\users\views.py", line 27, in create
    user = serializer.objects.get('user') or request.user
AttributeError: 'UserRegisterModelSeralizer' object has no attribute 'objects'
ERROR 2021-06-12 23:48:17,579 basehttp 161 "POST /user/register/ HTTP/1.1" 500 102115
INFO 2021-06-12 23:55:04,066 autoreload 636 Watching for file changes with StatReloader
INFO 2021-06-12 23:56:37,826 autoreload 636 Watching for file changes with StatReloader
INFO 2021-06-13 00:00:43,633 autoreload 636 Watching for file changes with StatReloader
ERROR 2021-06-13 00:00:49,893 log 224 Internal Server Error: /user/login/
Traceback (most recent call last):
  File "F:\Python\Python_Venv\Django_AutoTest\lib\site-packages\django\core\handlers\exception.py", line 47, in inner
    response = get_response(request)
  File "F:\Python\Python_Venv\Django_AutoTest\lib\site-packages\django\core\handlers\base.py", line 204, in _get_response
    response = response.render()
  File "F:\Python\Python_Venv\Django_AutoTest\lib\site-packages\django\template\response.py", line 105, in render
    self.content = self.rendered_content
  File "F:\Python\Python_Venv\Django_AutoTest\lib\site-packages\rest_framework\response.py", line 70, in rendered_content
    ret = renderer.render(self.data, accepted_media_type, context)
  File "F:\Python\Python_Venv\Django_AutoTest\lib\site-packages\rest_framework\renderers.py", line 100, in render
    ret = json.dumps(
  File "F:\Python\Python_Venv\Django_AutoTest\lib\site-packages\rest_framework\utils\json.py", line 25, in dumps
    return json.dumps(*args, **kwargs)
  File "F:\Python\Python39\lib\json\__init__.py", line 234, in dumps
    return cls(
  File "F:\Python\Python39\lib\json\encoder.py", line 199, in encode
    chunks = self.iterencode(o, _one_shot=True)
  File "F:\Python\Python39\lib\json\encoder.py", line 257, in iterencode
    return _iterencode(o, 0)
  File "F:\Python\Python_Venv\Django_AutoTest\lib\site-packages\rest_framework\utils\encoders.py", line 67, in default
    return super().default(obj)
  File "F:\Python\Python39\lib\json\encoder.py", line 179, in default
    raise TypeError(f'Object of type {o.__class__.__name__} '
TypeError: Object of type User is not JSON serializable
ERROR 2021-06-13 00:00:49,903 basehttp 161 "POST /user/login/ HTTP/1.1" 500 106508
ERROR 2021-06-13 00:01:00,610 log 224 Internal Server Error: /user/login/
Traceback (most recent call last):
  File "F:\Python\Python_Venv\Django_AutoTest\lib\site-packages\django\core\handlers\exception.py", line 47, in inner
    response = get_response(request)
  File "F:\Python\Python_Venv\Django_AutoTest\lib\site-packages\django\core\handlers\base.py", line 204, in _get_response
    response = response.render()
  File "F:\Python\Python_Venv\Django_AutoTest\lib\site-packages\django\template\response.py", line 105, in render
    self.content = self.rendered_content
  File "F:\Python\Python_Venv\Django_AutoTest\lib\site-packages\rest_framework\response.py", line 70, in rendered_content
    ret = renderer.render(self.data, accepted_media_type, context)
  File "F:\Python\Python_Venv\Django_AutoTest\lib\site-packages\rest_framework\renderers.py", line 100, in render
    ret = json.dumps(
  File "F:\Python\Python_Venv\Django_AutoTest\lib\site-packages\rest_framework\utils\json.py", line 25, in dumps
    return json.dumps(*args, **kwargs)
  File "F:\Python\Python39\lib\json\__init__.py", line 234, in dumps
    return cls(
  File "F:\Python\Python39\lib\json\encoder.py", line 199, in encode
    chunks = self.iterencode(o, _one_shot=True)
  File "F:\Python\Python39\lib\json\encoder.py", line 257, in iterencode
    return _iterencode(o, 0)
  File "F:\Python\Python_Venv\Django_AutoTest\lib\site-packages\rest_framework\utils\encoders.py", line 67, in default
    return super().default(obj)
  File "F:\Python\Python39\lib\json\encoder.py", line 179, in default
    raise TypeError(f'Object of type {o.__class__.__name__} '
TypeError: Object of type User is not JSON serializable
ERROR 2021-06-13 00:01:00,616 basehttp 161 "POST /user/login/ HTTP/1.1" 500 106508
INFO 2021-06-13 00:01:19,584 autoreload 250 F:\Python\Python_Project\python_test_developer\utils\jwt.py changed, reloading.
INFO 2021-06-13 00:01:22,136 autoreload 636 Watching for file changes with StatReloader
INFO 2021-06-13 00:01:24,966 basehttp 161 "POST /user/login/ HTTP/1.1" 200 197
INFO 2021-06-13 00:01:39,878 basehttp 161 "POST /user/login/ HTTP/1.1" 200 197
INFO 2021-06-13 00:01:42,000 basehttp 161 "POST /user/login/ HTTP/1.1" 200 197
INFO 2021-06-13 00:01:49,968 autoreload 636 Watching for file changes with StatReloader
INFO 2021-06-13 00:09:12,369 autoreload 636 Watching for file changes with StatReloader
WARNING 2021-06-13 00:09:19,266 log 224 Bad Request: /user/register/
WARNING 2021-06-13 00:09:19,268 basehttp 161 "POST /user/register/ HTTP/1.1" 400 59
ERROR 2021-06-13 00:09:27,422 log 224 Internal Server Error: /user/register/
Traceback (most recent call last):
  File "F:\Python\Python_Venv\Django_AutoTest\lib\site-packages\django\core\handlers\exception.py", line 47, in inner
    response = get_response(request)
  File "F:\Python\Python_Venv\Django_AutoTest\lib\site-packages\django\core\handlers\base.py", line 181, in _get_response
    response = wrapped_callback(request, *callback_args, **callback_kwargs)
  File "F:\Python\Python_Venv\Django_AutoTest\lib\site-packages\django\views\decorators\csrf.py", line 54, in wrapped_view
    return view_func(*args, **kwargs)
  File "F:\Python\Python_Venv\Django_AutoTest\lib\site-packages\rest_framework\viewsets.py", line 125, in view
    return self.dispatch(request, *args, **kwargs)
  File "F:\Python\Python_Venv\Django_AutoTest\lib\site-packages\rest_framework\views.py", line 509, in dispatch
    response = self.handle_exception(exc)
  File "F:\Python\Python_Venv\Django_AutoTest\lib\site-packages\rest_framework\views.py", line 469, in handle_exception
    self.raise_uncaught_exception(exc)
  File "F:\Python\Python_Venv\Django_AutoTest\lib\site-packages\rest_framework\views.py", line 480, in raise_uncaught_exception
    raise exc
  File "F:\Python\Python_Venv\Django_AutoTest\lib\site-packages\rest_framework\views.py", line 506, in dispatch
    response = handler(request, *args, **kwargs)
  File "F:\Python\Python_Project\python_test_developer\users\views.py", line 22, in create
    queryset = User.objects.create_user(**serializer.validated_data)
  File "F:\Python\Python_Venv\Django_AutoTest\lib\site-packages\django\contrib\auth\models.py", line 152, in create_user
    return self._create_user(username, email, password, **extra_fields)
  File "F:\Python\Python_Venv\Django_AutoTest\lib\site-packages\django\contrib\auth\models.py", line 144, in _create_user
    user = self.model(username=username, email=email, **extra_fields)
  File "F:\Python\Python_Venv\Django_AutoTest\lib\site-packages\django\db\models\base.py", line 503, in __init__
    raise TypeError("%s() got an unexpected keyword argument '%s'" % (cls.__name__, kwarg))
TypeError: User() got an unexpected keyword argument 'password_confirm'
ERROR 2021-06-13 00:09:27,431 basehttp 161 "POST /user/register/ HTTP/1.1" 500 116782
INFO 2021-06-13 00:09:52,704 autoreload 250 F:\Python\Python_Project\python_test_developer\users\views.py changed, reloading.
INFO 2021-06-13 00:11:43,910 autoreload 636 Watching for file changes with StatReloader
ERROR 2021-06-13 00:11:46,641 log 224 Internal Server Error: /user/register/
Traceback (most recent call last):
  File "F:\Python\Python_Venv\Django_AutoTest\lib\site-packages\django\core\handlers\exception.py", line 47, in inner
    response = get_response(request)
  File "F:\Python\Python_Venv\Django_AutoTest\lib\site-packages\django\core\handlers\base.py", line 181, in _get_response
    response = wrapped_callback(request, *callback_args, **callback_kwargs)
  File "F:\Python\Python_Venv\Django_AutoTest\lib\site-packages\django\views\decorators\csrf.py", line 54, in wrapped_view
    return view_func(*args, **kwargs)
  File "F:\Python\Python_Venv\Django_AutoTest\lib\site-packages\rest_framework\viewsets.py", line 125, in view
    return self.dispatch(request, *args, **kwargs)
  File "F:\Python\Python_Venv\Django_AutoTest\lib\site-packages\rest_framework\views.py", line 509, in dispatch
    response = self.handle_exception(exc)
  File "F:\Python\Python_Venv\Django_AutoTest\lib\site-packages\rest_framework\views.py", line 469, in handle_exception
    self.raise_uncaught_exception(exc)
  File "F:\Python\Python_Venv\Django_AutoTest\lib\site-packages\rest_framework\views.py", line 480, in raise_uncaught_exception
    raise exc
  File "F:\Python\Python_Venv\Django_AutoTest\lib\site-packages\rest_framework\views.py", line 506, in dispatch
    response = handler(request, *args, **kwargs)
  File "F:\Python\Python_Project\python_test_developer\users\views.py", line 24, in create
    payload = self.jwt_payload_handler(queryset)
AttributeError: 'UserRegisterViewSet' object has no attribute 'jwt_payload_handler'
ERROR 2021-06-13 00:11:46,652 basehttp 161 "POST /user/register/ HTTP/1.1" 500 100754
INFO 2021-06-13 00:16:59,442 autoreload 636 Watching for file changes with StatReloader
WARNING 2021-06-13 00:17:03,213 log 224 Bad Request: /user/register/
WARNING 2021-06-13 00:17:03,216 basehttp 161 "POST /user/register/ HTTP/1.1" 400 59
ERROR 2021-06-13 00:17:17,041 log 224 Internal Server Error: /user/register/
Traceback (most recent call last):
  File "F:\Python\Python_Venv\Django_AutoTest\lib\site-packages\django\core\handlers\exception.py", line 47, in inner
    response = get_response(request)
  File "F:\Python\Python_Venv\Django_AutoTest\lib\site-packages\django\core\handlers\base.py", line 181, in _get_response
    response = wrapped_callback(request, *callback_args, **callback_kwargs)
  File "F:\Python\Python_Venv\Django_AutoTest\lib\site-packages\django\views\decorators\csrf.py", line 54, in wrapped_view
    return view_func(*args, **kwargs)
  File "F:\Python\Python_Venv\Django_AutoTest\lib\site-packages\rest_framework\viewsets.py", line 125, in view
    return self.dispatch(request, *args, **kwargs)
  File "F:\Python\Python_Venv\Django_AutoTest\lib\site-packages\rest_framework\views.py", line 509, in dispatch
    response = self.handle_exception(exc)
  File "F:\Python\Python_Venv\Django_AutoTest\lib\site-packages\rest_framework\views.py", line 469, in handle_exception
    self.raise_uncaught_exception(exc)
  File "F:\Python\Python_Venv\Django_AutoTest\lib\site-packages\rest_framework\views.py", line 480, in raise_uncaught_exception
    raise exc
  File "F:\Python\Python_Venv\Django_AutoTest\lib\site-packages\rest_framework\views.py", line 506, in dispatch
    response = handler(request, *args, **kwargs)
  File "F:\Python\Python_Project\python_test_developer\users\views.py", line 24, in create
    payload = self.jwt_payload_handler(queryset)
AttributeError: 'UserRegisterViewSet' object has no attribute 'jwt_payload_handler'
ERROR 2021-06-13 00:17:17,048 basehttp 161 "POST /user/register/ HTTP/1.1" 500 101026
WARNING 2021-06-13 00:17:27,212 log 224 Bad Request: /user/register/
WARNING 2021-06-13 00:17:27,214 basehttp 161 "POST /user/register/ HTTP/1.1" 400 59
INFO 2021-06-13 00:19:14,848 autoreload 636 Watching for file changes with StatReloader
ERROR 2021-06-13 00:19:38,386 log 224 Internal Server Error: /user/register/
Traceback (most recent call last):
  File "F:\Python\Python_Venv\Django_AutoTest\lib\site-packages\django\core\handlers\exception.py", line 47, in inner
    response = get_response(request)
  File "F:\Python\Python_Venv\Django_AutoTest\lib\site-packages\django\core\handlers\base.py", line 181, in _get_response
    response = wrapped_callback(request, *callback_args, **callback_kwargs)
  File "F:\Python\Python_Venv\Django_AutoTest\lib\site-packages\django\views\decorators\csrf.py", line 54, in wrapped_view
    return view_func(*args, **kwargs)
  File "F:\Python\Python_Venv\Django_AutoTest\lib\site-packages\rest_framework\viewsets.py", line 125, in view
    return self.dispatch(request, *args, **kwargs)
  File "F:\Python\Python_Venv\Django_AutoTest\lib\site-packages\rest_framework\views.py", line 509, in dispatch
    response = self.handle_exception(exc)
  File "F:\Python\Python_Venv\Django_AutoTest\lib\site-packages\rest_framework\views.py", line 469, in handle_exception
    self.raise_uncaught_exception(exc)
  File "F:\Python\Python_Venv\Django_AutoTest\lib\site-packages\rest_framework\views.py", line 480, in raise_uncaught_exception
    raise exc
  File "F:\Python\Python_Venv\Django_AutoTest\lib\site-packages\rest_framework\views.py", line 506, in dispatch
    response = handler(request, *args, **kwargs)
  File "F:\Python\Python_Project\python_test_developer\users\views.py", line 29, in create
    response_data = self.jwt_response_payload_handler(
AttributeError: 'UserRegisterViewSet' object has no attribute 'jwt_response_payload_handler'
ERROR 2021-06-13 00:19:38,399 basehttp 161 "POST /user/register/ HTTP/1.1" 500 102364
INFO 2021-06-13 00:21:05,507 autoreload 250 F:\Python\Python_Project\python_test_developer\users\views.py changed, reloading.
INFO 2021-06-13 00:21:07,916 autoreload 636 Watching for file changes with StatReloader
INFO 2021-06-13 00:21:51,311 autoreload 636 Watching for file changes with StatReloader
INFO 2021-06-13 00:22:35,059 basehttp 161 "POST /user/register/ HTTP/1.1" 200 199
INFO 2021-06-13 00:25:03,711 autoreload 250 F:\Python\Python_Project\python_test_developer\utils\jwt.py changed, reloading.
INFO 2021-06-13 00:25:06,210 autoreload 636 Watching for file changes with StatReloader
INFO 2021-06-13 00:25:35,139 autoreload 636 Watching for file changes with StatReloader
INFO 2021-06-13 00:25:52,237 basehttp 161 "POST /user/register/ HTTP/1.1" 200 221
INFO 2021-06-13 00:27:10,966 autoreload 636 Watching for file changes with StatReloader
WARNING 2021-06-13 00:27:13,468 log 224 Bad Request: /user/register/
WARNING 2021-06-13 00:27:13,471 basehttp 161 "POST /user/register/ HTTP/1.1" 400 46
WARNING 2021-06-13 00:28:03,526 log 224 Bad Request: /user/register/
WARNING 2021-06-13 00:28:03,528 basehttp 161 "POST /user/register/ HTTP/1.1" 400 109
WARNING 2021-06-13 00:28:11,838 log 224 Bad Request: /user/register/
WARNING 2021-06-13 00:28:11,839 basehttp 161 "POST /user/register/ HTTP/1.1" 400 96
INFO 2021-06-13 00:33:13,881 autoreload 636 Watching for file changes with StatReloader
WARNING 2021-06-13 00:33:16,621 log 224 Not Found: /user/register/
WARNING 2021-06-13 00:33:16,622 basehttp 161 "POST /user/register/ HTTP/1.1" 404 2723
INFO 2021-06-13 00:33:30,607 autoreload 250 F:\Python\Python_Project\python_test_developer\users\urls.py changed, reloading.
INFO 2021-06-13 00:33:33,098 autoreload 636 Watching for file changes with StatReloader
WARNING 2021-06-13 00:33:36,830 log 224 Bad Request: /user/register/
WARNING 2021-06-13 00:33:36,833 basehttp 161 "POST /user/register/ HTTP/1.1" 400 96
INFO 2021-06-13 00:35:17,115 autoreload 250 F:\Python\Python_Project\python_test_developer\users\urls.py changed, reloading.
INFO 2021-06-13 00:35:19,289 autoreload 636 Watching for file changes with StatReloader
INFO 2021-06-13 23:05:29,920 autoreload 636 Watching for file changes with StatReloader
INFO 2021-06-13 23:11:43,057 autoreload 250 F:\Python\Python_Project\python_test_developer\users\views.py changed, reloading.
INFO 2021-06-13 23:25:25,076 autoreload 636 Watching for file changes with StatReloader
INFO 2021-06-13 23:26:01,190 autoreload 636 Watching for file changes with StatReloader
INFO 2021-06-13 23:26:57,210 autoreload 250 F:\Python\Python_Project\python_test_developer\users\views.py changed, reloading.
INFO 2021-06-13 23:27:11,031 autoreload 636 Watching for file changes with StatReloader
ERROR 2021-06-13 23:27:34,875 log 224 Internal Server Error: /user/sunwang/count/
Traceback (most recent call last):
  File "F:\Python\Python_Venv\Django_AutoTest\lib\site-packages\django\core\handlers\exception.py", line 47, in inner
    response = get_response(request)
  File "F:\Python\Python_Venv\Django_AutoTest\lib\site-packages\django\core\handlers\base.py", line 181, in _get_response
    response = wrapped_callback(request, *callback_args, **callback_kwargs)
  File "F:\Python\Python_Venv\Django_AutoTest\lib\site-packages\django\views\decorators\csrf.py", line 54, in wrapped_view
    return view_func(*args, **kwargs)
  File "F:\Python\Python_Venv\Django_AutoTest\lib\site-packages\rest_framework\viewsets.py", line 125, in view
    return self.dispatch(request, *args, **kwargs)
  File "F:\Python\Python_Venv\Django_AutoTest\lib\site-packages\rest_framework\views.py", line 509, in dispatch
    response = self.handle_exception(exc)
  File "F:\Python\Python_Venv\Django_AutoTest\lib\site-packages\rest_framework\views.py", line 469, in handle_exception
    self.raise_uncaught_exception(exc)
  File "F:\Python\Python_Venv\Django_AutoTest\lib\site-packages\rest_framework\views.py", line 480, in raise_uncaught_exception
    raise exc
  File "F:\Python\Python_Venv\Django_AutoTest\lib\site-packages\rest_framework\views.py", line 506, in dispatch
    response = handler(request, *args, **kwargs)
  File "F:\Python\Python_Project\python_test_developer\users\views.py", line 53, in cont_username_email
    url_parmar_email = re.match(
AttributeError: 'NoneType' object has no attribute 'group'
ERROR 2021-06-13 23:27:34,888 basehttp 161 "GET /user/sunwang/count/ HTTP/1.1" 500 99087
INFO 2021-06-13 23:30:45,603 autoreload 250 F:\Python\Python_Project\python_test_developer\users\views.py changed, reloading.
INFO 2021-06-13 23:30:47,983 autoreload 636 Watching for file changes with StatReloader
INFO 2021-06-13 23:40:14,716 autoreload 636 Watching for file changes with StatReloader
ERROR 2021-06-13 23:40:27,546 log 224 Internal Server Error: /user/sunwang/count/
Traceback (most recent call last):
  File "F:\Python\Python_Venv\Django_AutoTest\lib\site-packages\django\core\handlers\exception.py", line 47, in inner
    response = get_response(request)
  File "F:\Python\Python_Venv\Django_AutoTest\lib\site-packages\django\core\handlers\base.py", line 181, in _get_response
    response = wrapped_callback(request, *callback_args, **callback_kwargs)
  File "F:\Python\Python_Venv\Django_AutoTest\lib\site-packages\django\views\decorators\csrf.py", line 54, in wrapped_view
    return view_func(*args, **kwargs)
  File "F:\Python\Python_Venv\Django_AutoTest\lib\site-packages\rest_framework\viewsets.py", line 125, in view
    return self.dispatch(request, *args, **kwargs)
  File "F:\Python\Python_Venv\Django_AutoTest\lib\site-packages\rest_framework\views.py", line 509, in dispatch
    response = self.handle_exception(exc)
  File "F:\Python\Python_Venv\Django_AutoTest\lib\site-packages\rest_framework\views.py", line 469, in handle_exception
    self.raise_uncaught_exception(exc)
  File "F:\Python\Python_Venv\Django_AutoTest\lib\site-packages\rest_framework\views.py", line 480, in raise_uncaught_exception
    raise exc
  File "F:\Python\Python_Venv\Django_AutoTest\lib\site-packages\rest_framework\views.py", line 506, in dispatch
    response = handler(request, *args, **kwargs)
  File "F:\Python\Python_Project\python_test_developer\users\views.py", line 53, in cont_username_email
    url_parmar_email = re.findall(
  File "F:\Python\Python39\lib\re.py", line 241, in findall
    return _compile(pattern, flags).findall(string)
TypeError: expected string or bytes-like object
ERROR 2021-06-13 23:40:27,557 basehttp 161 "GET /user/sunwang/count/ HTTP/1.1" 500 102818
INFO 2021-06-13 23:40:58,853 autoreload 250 F:\Python\Python_Project\python_test_developer\users\views.py changed, reloading.
INFO 2021-06-13 23:41:40,474 autoreload 636 Watching for file changes with StatReloader
INFO 2021-06-13 23:41:58,363 autoreload 250 F:\Python\Python_Project\python_test_developer\users\views.py changed, reloading.
INFO 2021-06-13 23:42:06,590 autoreload 636 Watching for file changes with StatReloader
ERROR 2021-06-13 23:42:13,862 log 224 Internal Server Error: /user/sunwang/count/
Traceback (most recent call last):
  File "F:\Python\Python_Venv\Django_AutoTest\lib\site-packages\django\core\handlers\exception.py", line 47, in inner
    response = get_response(request)
  File "F:\Python\Python_Venv\Django_AutoTest\lib\site-packages\django\core\handlers\base.py", line 181, in _get_response
    response = wrapped_callback(request, *callback_args, **callback_kwargs)
  File "F:\Python\Python_Venv\Django_AutoTest\lib\site-packages\django\views\decorators\csrf.py", line 54, in wrapped_view
    return view_func(*args, **kwargs)
  File "F:\Python\Python_Venv\Django_AutoTest\lib\site-packages\rest_framework\viewsets.py", line 125, in view
    return self.dispatch(request, *args, **kwargs)
  File "F:\Python\Python_Venv\Django_AutoTest\lib\site-packages\rest_framework\views.py", line 509, in dispatch
    response = self.handle_exception(exc)
  File "F:\Python\Python_Venv\Django_AutoTest\lib\site-packages\rest_framework\views.py", line 469, in handle_exception
    self.raise_uncaught_exception(exc)
  File "F:\Python\Python_Venv\Django_AutoTest\lib\site-packages\rest_framework\views.py", line 480, in raise_uncaught_exception
    raise exc
  File "F:\Python\Python_Venv\Django_AutoTest\lib\site-packages\rest_framework\views.py", line 506, in dispatch
    response = handler(request, *args, **kwargs)
  File "F:\Python\Python_Project\python_test_developer\users\views.py", line 59, in cont_username_email
    queryset = self.get_queryset(username=url_parmar[0])
TypeError: get_queryset() got an unexpected keyword argument 'username'
ERROR 2021-06-13 23:42:13,874 basehttp 161 "GET /user/sunwang/count/ HTTP/1.1" 500 99105
INFO 2021-06-13 23:50:14,751 autoreload 636 Watching for file changes with StatReloader
INFO 2021-06-13 23:53:33,748 basehttp 75 - Broken pipe from ('127.0.0.1', 6922)

INFO 2021-06-13 23:53:44,351 basehttp 161 "GET /user/sunwang/count/ HTTP/1.1" 200 11
INFO 2021-06-13 23:55:06,631 autoreload 636 Watching for file changes with StatReloader
ERROR 2021-06-13 23:55:14,131 log 224 Internal Server Error: /user/641210592@qq.com/count/
Traceback (most recent call last):
  File "F:\Python\Python_Venv\Django_AutoTest\lib\site-packages\django\core\handlers\exception.py", line 47, in inner
    response = get_response(request)
  File "F:\Python\Python_Venv\Django_AutoTest\lib\site-packages\django\core\handlers\base.py", line 181, in _get_response
    response = wrapped_callback(request, *callback_args, **callback_kwargs)
  File "F:\Python\Python_Venv\Django_AutoTest\lib\site-packages\django\views\decorators\csrf.py", line 54, in wrapped_view
    return view_func(*args, **kwargs)
  File "F:\Python\Python_Venv\Django_AutoTest\lib\site-packages\rest_framework\viewsets.py", line 125, in view
    return self.dispatch(request, *args, **kwargs)
  File "F:\Python\Python_Venv\Django_AutoTest\lib\site-packages\rest_framework\views.py", line 509, in dispatch
    response = self.handle_exception(exc)
  File "F:\Python\Python_Venv\Django_AutoTest\lib\site-packages\rest_framework\views.py", line 469, in handle_exception
    self.raise_uncaught_exception(exc)
  File "F:\Python\Python_Venv\Django_AutoTest\lib\site-packages\rest_framework\views.py", line 480, in raise_uncaught_exception
    raise exc
  File "F:\Python\Python_Venv\Django_AutoTest\lib\site-packages\rest_framework\views.py", line 506, in dispatch
    response = handler(request, *args, **kwargs)
  File "F:\Python\Python_Project\python_test_developer\users\views.py", line 57, in cont_username_email
    queryset = User.objects.filter(emali=url_parmar_email[0])
  File "F:\Python\Python_Venv\Django_AutoTest\lib\site-packages\django\db\models\manager.py", line 85, in manager_method
    return getattr(self.get_queryset(), name)(*args, **kwargs)
  File "F:\Python\Python_Venv\Django_AutoTest\lib\site-packages\django\db\models\query.py", line 941, in filter
    return self._filter_or_exclude(False, args, kwargs)
  File "F:\Python\Python_Venv\Django_AutoTest\lib\site-packages\django\db\models\query.py", line 961, in _filter_or_exclude
    clone._filter_or_exclude_inplace(negate, args, kwargs)
  File "F:\Python\Python_Venv\Django_AutoTest\lib\site-packages\django\db\models\query.py", line 968, in _filter_or_exclude_inplace
    self._query.add_q(Q(*args, **kwargs))
  File "F:\Python\Python_Venv\Django_AutoTest\lib\site-packages\django\db\models\sql\query.py", line 1391, in add_q
    clause, _ = self._add_q(q_object, self.used_aliases)
  File "F:\Python\Python_Venv\Django_AutoTest\lib\site-packages\django\db\models\sql\query.py", line 1410, in _add_q
    child_clause, needed_inner = self.build_filter(
  File "F:\Python\Python_Venv\Django_AutoTest\lib\site-packages\django\db\models\sql\query.py", line 1284, in build_filter
    lookups, parts, reffed_expression = self.solve_lookup_type(arg)
  File "F:\Python\Python_Venv\Django_AutoTest\lib\site-packages\django\db\models\sql\query.py", line 1110, in solve_lookup_type
    _, field, _, lookup_parts = self.names_to_path(lookup_splitted, self.get_meta())
  File "F:\Python\Python_Venv\Django_AutoTest\lib\site-packages\django\db\models\sql\query.py", line 1537, in names_to_path
    raise FieldError("Cannot resolve keyword '%s' into field. "
django.core.exceptions.FieldError: Cannot resolve keyword 'emali' into field. Choices are: date_joined, email, first_name, groups, id, is_active, is_staff, is_superuser, last_login, last_name, logentry, password, user_permissions, username
ERROR 2021-06-13 23:55:14,143 basehttp 161 "GET /user/641210592@qq.com/count/ HTTP/1.1" 500 144139
ERROR 2021-06-13 23:56:29,859 log 224 Internal Server Error: /user/641210592@qq.com/count/
Traceback (most recent call last):
  File "F:\Python\Python_Venv\Django_AutoTest\lib\site-packages\django\core\handlers\exception.py", line 47, in inner
    response = get_response(request)
  File "F:\Python\Python_Venv\Django_AutoTest\lib\site-packages\django\core\handlers\base.py", line 181, in _get_response
    response = wrapped_callback(request, *callback_args, **callback_kwargs)
  File "F:\Python\Python_Venv\Django_AutoTest\lib\site-packages\django\views\decorators\csrf.py", line 54, in wrapped_view
    return view_func(*args, **kwargs)
  File "F:\Python\Python_Venv\Django_AutoTest\lib\site-packages\rest_framework\viewsets.py", line 125, in view
    return self.dispatch(request, *args, **kwargs)
  File "F:\Python\Python_Venv\Django_AutoTest\lib\site-packages\rest_framework\views.py", line 509, in dispatch
    response = self.handle_exception(exc)
  File "F:\Python\Python_Venv\Django_AutoTest\lib\site-packages\rest_framework\views.py", line 469, in handle_exception
    self.raise_uncaught_exception(exc)
  File "F:\Python\Python_Venv\Django_AutoTest\lib\site-packages\rest_framework\views.py", line 480, in raise_uncaught_exception
    raise exc
  File "F:\Python\Python_Venv\Django_AutoTest\lib\site-packages\rest_framework\views.py", line 506, in dispatch
    response = handler(request, *args, **kwargs)
  File "F:\Python\Python_Project\python_test_developer\users\views.py", line 57, in cont_username_email
    queryset = User.objects.filter(emali=url_parmar_email[0])
  File "F:\Python\Python_Venv\Django_AutoTest\lib\site-packages\django\db\models\manager.py", line 85, in manager_method
    return getattr(self.get_queryset(), name)(*args, **kwargs)
  File "F:\Python\Python_Venv\Django_AutoTest\lib\site-packages\django\db\models\query.py", line 941, in filter
    return self._filter_or_exclude(False, args, kwargs)
  File "F:\Python\Python_Venv\Django_AutoTest\lib\site-packages\django\db\models\query.py", line 961, in _filter_or_exclude
    clone._filter_or_exclude_inplace(negate, args, kwargs)
  File "F:\Python\Python_Venv\Django_AutoTest\lib\site-packages\django\db\models\query.py", line 968, in _filter_or_exclude_inplace
    self._query.add_q(Q(*args, **kwargs))
  File "F:\Python\Python_Venv\Django_AutoTest\lib\site-packages\django\db\models\sql\query.py", line 1391, in add_q
    clause, _ = self._add_q(q_object, self.used_aliases)
  File "F:\Python\Python_Venv\Django_AutoTest\lib\site-packages\django\db\models\sql\query.py", line 1410, in _add_q
    child_clause, needed_inner = self.build_filter(
  File "F:\Python\Python_Venv\Django_AutoTest\lib\site-packages\django\db\models\sql\query.py", line 1284, in build_filter
    lookups, parts, reffed_expression = self.solve_lookup_type(arg)
  File "F:\Python\Python_Venv\Django_AutoTest\lib\site-packages\django\db\models\sql\query.py", line 1110, in solve_lookup_type
    _, field, _, lookup_parts = self.names_to_path(lookup_splitted, self.get_meta())
  File "F:\Python\Python_Venv\Django_AutoTest\lib\site-packages\django\db\models\sql\query.py", line 1537, in names_to_path
    raise FieldError("Cannot resolve keyword '%s' into field. "
django.core.exceptions.FieldError: Cannot resolve keyword 'emali' into field. Choices are: date_joined, email, first_name, groups, id, is_active, is_staff, is_superuser, last_login, last_name, logentry, password, user_permissions, username
ERROR 2021-06-13 23:56:29,872 basehttp 161 "GET /user/641210592@qq.com/count/ HTTP/1.1" 500 144501
INFO 2021-06-13 23:56:47,984 autoreload 250 F:\Python\Python_Project\python_test_developer\users\views.py changed, reloading.
INFO 2021-06-13 23:56:50,294 autoreload 636 Watching for file changes with StatReloader
INFO 2021-06-13 23:56:56,133 basehttp 161 "GET /user/641210592@qq.com/count/ HTTP/1.1" 200 11
INFO 2021-06-13 23:58:25,707 autoreload 250 F:\Python\Python_Project\python_test_developer\users\views.py changed, reloading.
INFO 2021-06-13 23:58:46,434 autoreload 636 Watching for file changes with StatReloader
INFO 2021-06-13 23:58:53,985 basehttp 161 "GET /user/641210592@qq.com/count/ HTTP/1.1" 200 11
INFO 2021-06-13 23:59:06,370 autoreload 250 F:\Python\Python_Project\python_test_developer\users\views.py changed, reloading.
INFO 2021-06-13 23:59:08,740 autoreload 636 Watching for file changes with StatReloader
INFO 2021-06-14 00:11:22,253 autoreload 636 Watching for file changes with StatReloader
INFO 2021-06-14 00:11:27,349 basehttp 161 "GET /user/641210592@qq.com/count/ HTTP/1.1" 200 11
INFO 2021-06-14 00:11:31,410 basehttp 161 "GET /user/sunwang/count/ HTTP/1.1" 200 11
INFO 2021-06-14 00:13:01,715 autoreload 250 F:\Python\Python_Project\python_test_developer\users\serializers.py changed, reloading.
INFO 2021-06-14 00:13:29,744 autoreload 636 Watching for file changes with StatReloader
INFO 2021-06-14 00:13:33,558 basehttp 161 "GET /user/sunwang/count/ HTTP/1.1" 200 11
INFO 2021-06-14 00:14:35,056 autoreload 250 F:\Python\Python_Project\python_test_developer\users\serializers.py changed, reloading.
INFO 2021-06-14 00:14:37,390 autoreload 636 Watching for file changes with StatReloader
INFO 2021-06-14 00:25:04,607 autoreload 636 Watching for file changes with StatReloader
ERROR 2021-06-14 00:25:07,790 log 224 Internal Server Error: /user/register/
Traceback (most recent call last):
  File "F:\Python\Python_Venv\Django_AutoTest\lib\site-packages\django\core\handlers\exception.py", line 47, in inner
    response = get_response(request)
  File "F:\Python\Python_Venv\Django_AutoTest\lib\site-packages\django\core\handlers\base.py", line 181, in _get_response
    response = wrapped_callback(request, *callback_args, **callback_kwargs)
  File "F:\Python\Python_Venv\Django_AutoTest\lib\site-packages\django\views\decorators\csrf.py", line 54, in wrapped_view
    return view_func(*args, **kwargs)
  File "F:\Python\Python_Venv\Django_AutoTest\lib\site-packages\rest_framework\viewsets.py", line 125, in view
    return self.dispatch(request, *args, **kwargs)
  File "F:\Python\Python_Venv\Django_AutoTest\lib\site-packages\rest_framework\views.py", line 509, in dispatch
    response = self.handle_exception(exc)
  File "F:\Python\Python_Venv\Django_AutoTest\lib\site-packages\rest_framework\views.py", line 469, in handle_exception
    self.raise_uncaught_exception(exc)
  File "F:\Python\Python_Venv\Django_AutoTest\lib\site-packages\rest_framework\views.py", line 480, in raise_uncaught_exception
    raise exc
  File "F:\Python\Python_Venv\Django_AutoTest\lib\site-packages\rest_framework\views.py", line 506, in dispatch
    response = handler(request, *args, **kwargs)
  File "F:\Python\Python_Project\python_test_developer\users\views.py", line 24, in create
    if serializer.is_valid(raise_exception=True):
  File "F:\Python\Python_Venv\Django_AutoTest\lib\site-packages\rest_framework\serializers.py", line 220, in is_valid
    self._validated_data = self.run_validation(self.initial_data)
  File "F:\Python\Python_Venv\Django_AutoTest\lib\site-packages\rest_framework\serializers.py", line 419, in run_validation
    value = self.to_internal_value(data)
  File "F:\Python\Python_Venv\Django_AutoTest\lib\site-packages\rest_framework\serializers.py", line 472, in to_internal_value
    for field in fields:
  File "F:\Python\Python_Venv\Django_AutoTest\lib\site-packages\rest_framework\serializers.py", line 355, in _writable_fields
    for field in self.fields.values():
  File "F:\Python\Python_Venv\Django_AutoTest\lib\site-packages\django\utils\functional.py", line 48, in __get__
    res = instance.__dict__[self.name] = self.func(instance)
  File "F:\Python\Python_Venv\Django_AutoTest\lib\site-packages\rest_framework\serializers.py", line 349, in fields
    for key, value in self.get_fields().items():
  File "F:\Python\Python_Venv\Django_AutoTest\lib\site-packages\rest_framework\serializers.py", line 1063, in get_fields
    fields[field_name] = field_class(**field_kwargs)
  File "F:\Python\Python_Venv\Django_AutoTest\lib\site-packages\rest_framework\fields.py", line 778, in __init__
    super().__init__(**kwargs)
TypeError: __init__() got an unexpected keyword argument 'miax_length'
ERROR 2021-06-14 00:25:07,800 basehttp 161 "POST /user/register/ HTTP/1.1" 500 138441
INFO 2021-06-14 00:25:16,272 autoreload 250 F:\Python\Python_Project\python_test_developer\users\serializers.py changed, reloading.
INFO 2021-06-14 00:25:18,596 autoreload 636 Watching for file changes with StatReloader
INFO 2021-06-14 00:25:21,269 autoreload 250 F:\Python\Python_Project\python_test_developer\users\serializers.py changed, reloading.
INFO 2021-06-14 00:25:23,651 autoreload 636 Watching for file changes with StatReloader
ERROR 2021-06-14 00:25:26,247 log 224 Internal Server Error: /user/register/
Traceback (most recent call last):
  File "F:\Python\Python_Venv\Django_AutoTest\lib\site-packages\django\core\handlers\exception.py", line 47, in inner
    response = get_response(request)
  File "F:\Python\Python_Venv\Django_AutoTest\lib\site-packages\django\core\handlers\base.py", line 181, in _get_response
    response = wrapped_callback(request, *callback_args, **callback_kwargs)
  File "F:\Python\Python_Venv\Django_AutoTest\lib\site-packages\django\views\decorators\csrf.py", line 54, in wrapped_view
    return view_func(*args, **kwargs)
  File "F:\Python\Python_Venv\Django_AutoTest\lib\site-packages\rest_framework\viewsets.py", line 125, in view
    return self.dispatch(request, *args, **kwargs)
  File "F:\Python\Python_Venv\Django_AutoTest\lib\site-packages\rest_framework\views.py", line 509, in dispatch
    response = self.handle_exception(exc)
  File "F:\Python\Python_Venv\Django_AutoTest\lib\site-packages\rest_framework\views.py", line 469, in handle_exception
    self.raise_uncaught_exception(exc)
  File "F:\Python\Python_Venv\Django_AutoTest\lib\site-packages\rest_framework\views.py", line 480, in raise_uncaught_exception
    raise exc
  File "F:\Python\Python_Venv\Django_AutoTest\lib\site-packages\rest_framework\views.py", line 506, in dispatch
    response = handler(request, *args, **kwargs)
  File "F:\Python\Python_Project\python_test_developer\users\views.py", line 24, in create
    if serializer.is_valid(raise_exception=True):
  File "F:\Python\Python_Venv\Django_AutoTest\lib\site-packages\rest_framework\serializers.py", line 220, in is_valid
    self._validated_data = self.run_validation(self.initial_data)
  File "F:\Python\Python_Venv\Django_AutoTest\lib\site-packages\rest_framework\serializers.py", line 419, in run_validation
    value = self.to_internal_value(data)
  File "F:\Python\Python_Venv\Django_AutoTest\lib\site-packages\rest_framework\serializers.py", line 472, in to_internal_value
    for field in fields:
  File "F:\Python\Python_Venv\Django_AutoTest\lib\site-packages\rest_framework\serializers.py", line 355, in _writable_fields
    for field in self.fields.values():
  File "F:\Python\Python_Venv\Django_AutoTest\lib\site-packages\django\utils\functional.py", line 48, in __get__
    res = instance.__dict__[self.name] = self.func(instance)
  File "F:\Python\Python_Venv\Django_AutoTest\lib\site-packages\rest_framework\serializers.py", line 349, in fields
    for key, value in self.get_fields().items():
  File "F:\Python\Python_Venv\Django_AutoTest\lib\site-packages\rest_framework\serializers.py", line 1063, in get_fields
    fields[field_name] = field_class(**field_kwargs)
  File "F:\Python\Python_Venv\Django_AutoTest\lib\site-packages\rest_framework\fields.py", line 778, in __init__
    super().__init__(**kwargs)
TypeError: __init__() got an unexpected keyword argument 'message'
ERROR 2021-06-14 00:25:26,258 basehttp 161 "POST /user/register/ HTTP/1.1" 500 138302
INFO 2021-06-14 00:25:40,278 autoreload 250 F:\Python\Python_Project\python_test_developer\users\serializers.py changed, reloading.
INFO 2021-06-14 00:25:42,633 autoreload 636 Watching for file changes with StatReloader
INFO 2021-06-14 00:25:45,346 autoreload 250 F:\Python\Python_Project\python_test_developer\users\serializers.py changed, reloading.
INFO 2021-06-14 00:28:06,242 autoreload 636 Watching for file changes with StatReloader
WARNING 2021-06-14 00:28:17,108 log 224 Bad Request: /user/register/
WARNING 2021-06-14 00:28:17,110 basehttp 161 "POST /user/register/ HTTP/1.1" 400 35
WARNING 2021-06-14 00:28:43,389 log 224 Bad Request: /user/register/
WARNING 2021-06-14 00:28:43,391 basehttp 161 "POST /user/register/ HTTP/1.1" 400 65
INFO 2021-06-14 00:30:05,674 autoreload 250 F:\Python\Python_Project\python_test_developer\users\serializers.py changed, reloading.
INFO 2021-06-14 00:30:07,829 autoreload 636 Watching for file changes with StatReloader
INFO 2021-06-14 00:30:42,857 autoreload 636 Watching for file changes with StatReloader
ERROR 2021-06-14 00:30:47,797 log 224 Internal Server Error: /user/register/
Traceback (most recent call last):
  File "F:\Python\Python_Venv\Django_AutoTest\lib\site-packages\django\core\handlers\exception.py", line 47, in inner
    response = get_response(request)
  File "F:\Python\Python_Venv\Django_AutoTest\lib\site-packages\django\core\handlers\base.py", line 181, in _get_response
    response = wrapped_callback(request, *callback_args, **callback_kwargs)
  File "F:\Python\Python_Venv\Django_AutoTest\lib\site-packages\django\views\decorators\csrf.py", line 54, in wrapped_view
    return view_func(*args, **kwargs)
  File "F:\Python\Python_Venv\Django_AutoTest\lib\site-packages\rest_framework\viewsets.py", line 125, in view
    return self.dispatch(request, *args, **kwargs)
  File "F:\Python\Python_Venv\Django_AutoTest\lib\site-packages\rest_framework\views.py", line 509, in dispatch
    response = self.handle_exception(exc)
  File "F:\Python\Python_Venv\Django_AutoTest\lib\site-packages\rest_framework\views.py", line 469, in handle_exception
    self.raise_uncaught_exception(exc)
  File "F:\Python\Python_Venv\Django_AutoTest\lib\site-packages\rest_framework\views.py", line 480, in raise_uncaught_exception
    raise exc
  File "F:\Python\Python_Venv\Django_AutoTest\lib\site-packages\rest_framework\views.py", line 506, in dispatch
    response = handler(request, *args, **kwargs)
  File "F:\Python\Python_Project\python_test_developer\users\views.py", line 24, in create
    if serializer.is_valid(raise_exception=True):
  File "F:\Python\Python_Venv\Django_AutoTest\lib\site-packages\rest_framework\serializers.py", line 220, in is_valid
    self._validated_data = self.run_validation(self.initial_data)
  File "F:\Python\Python_Venv\Django_AutoTest\lib\site-packages\rest_framework\serializers.py", line 419, in run_validation
    value = self.to_internal_value(data)
  File "F:\Python\Python_Venv\Django_AutoTest\lib\site-packages\rest_framework\serializers.py", line 472, in to_internal_value
    for field in fields:
  File "F:\Python\Python_Venv\Django_AutoTest\lib\site-packages\rest_framework\serializers.py", line 355, in _writable_fields
    for field in self.fields.values():
  File "F:\Python\Python_Venv\Django_AutoTest\lib\site-packages\django\utils\functional.py", line 48, in __get__
    res = instance.__dict__[self.name] = self.func(instance)
  File "F:\Python\Python_Venv\Django_AutoTest\lib\site-packages\rest_framework\serializers.py", line 349, in fields
    for key, value in self.get_fields().items():
  File "F:\Python\Python_Venv\Django_AutoTest\lib\site-packages\rest_framework\serializers.py", line 1063, in get_fields
    fields[field_name] = field_class(**field_kwargs)
  File "F:\Python\Python_Venv\Django_AutoTest\lib\site-packages\rest_framework\fields.py", line 778, in __init__
    super().__init__(**kwargs)
  File "F:\Python\Python_Venv\Django_AutoTest\lib\site-packages\rest_framework\fields.py", line 366, in __init__
    messages.update(error_messages or {})
ValueError: dictionary update sequence element #0 has length 1; 2 is required
ERROR 2021-06-14 00:30:47,808 basehttp 161 "POST /user/register/ HTTP/1.1" 500 147040
INFO 2021-06-14 00:31:33,945 autoreload 250 F:\Python\Python_Project\python_test_developer\users\serializers.py changed, reloading.
INFO 2021-06-14 00:31:36,269 autoreload 636 Watching for file changes with StatReloader
INFO 2021-06-14 00:38:47,408 autoreload 636 Watching for file changes with StatReloader
INFO 2021-06-14 00:39:27,171 basehttp 161 "GET /user/sunwang/count/ HTTP/1.1" 200 11
INFO 2021-06-14 00:39:34,102 basehttp 161 "GET /user/641210592@qq.com/count/ HTTP/1.1" 200 11
INFO 2021-06-14 00:40:05,112 basehttp 161 "GET /user/641210592@qq.com/count/ HTTP/1.1" 200 11
INFO 2021-06-14 00:44:49,855 autoreload 636 Watching for file changes with StatReloader
ERROR 2021-06-14 00:44:53,482 log 224 Internal Server Error: /user/641210592@qq.com/count/
Traceback (most recent call last):
  File "F:\Python\Python_Venv\Django_AutoTest\lib\site-packages\django\core\handlers\exception.py", line 47, in inner
    response = get_response(request)
  File "F:\Python\Python_Venv\Django_AutoTest\lib\site-packages\django\core\handlers\base.py", line 181, in _get_response
    response = wrapped_callback(request, *callback_args, **callback_kwargs)
  File "F:\Python\Python_Venv\Django_AutoTest\lib\site-packages\django\views\decorators\csrf.py", line 54, in wrapped_view
    return view_func(*args, **kwargs)
  File "F:\Python\Python_Venv\Django_AutoTest\lib\site-packages\rest_framework\viewsets.py", line 125, in view
    return self.dispatch(request, *args, **kwargs)
  File "F:\Python\Python_Venv\Django_AutoTest\lib\site-packages\rest_framework\views.py", line 509, in dispatch
    response = self.handle_exception(exc)
  File "F:\Python\Python_Venv\Django_AutoTest\lib\site-packages\rest_framework\views.py", line 469, in handle_exception
    self.raise_uncaught_exception(exc)
  File "F:\Python\Python_Venv\Django_AutoTest\lib\site-packages\rest_framework\views.py", line 480, in raise_uncaught_exception
    raise exc
  File "F:\Python\Python_Venv\Django_AutoTest\lib\site-packages\rest_framework\views.py", line 506, in dispatch
    response = handler(request, *args, **kwargs)
  File "F:\Python\Python_Project\python_test_developer\users\views.py", line 68, in count_username_email
    response_data = serializer.data
  File "F:\Python\Python_Venv\Django_AutoTest\lib\site-packages\rest_framework\serializers.py", line 548, in data
    ret = super().data
  File "F:\Python\Python_Venv\Django_AutoTest\lib\site-packages\rest_framework\serializers.py", line 246, in data
    self._data = self.to_representation(self.instance)
  File "F:\Python\Python_Venv\Django_AutoTest\lib\site-packages\rest_framework\serializers.py", line 500, in to_representation
    for field in fields:
  File "F:\Python\Python_Venv\Django_AutoTest\lib\site-packages\rest_framework\serializers.py", line 361, in _readable_fields
    for field in self.fields.values():
  File "F:\Python\Python_Venv\Django_AutoTest\lib\site-packages\django\utils\functional.py", line 48, in __get__
    res = instance.__dict__[self.name] = self.func(instance)
  File "F:\Python\Python_Venv\Django_AutoTest\lib\site-packages\rest_framework\serializers.py", line 349, in fields
    for key, value in self.get_fields().items():
  File "F:\Python\Python_Venv\Django_AutoTest\lib\site-packages\rest_framework\serializers.py", line 1004, in get_fields
    assert hasattr(self, 'Meta'), (
AssertionError: Class UserCountSeralizer missing "Meta" attribute
ERROR 2021-06-14 00:44:53,491 basehttp 161 "GET /user/641210592@qq.com/count/ HTTP/1.1" 500 126606
INFO 2021-06-14 00:45:08,732 autoreload 250 F:\Python\Python_Project\python_test_developer\users\serializers.py changed, reloading.
INFO 2021-06-14 00:45:10,956 autoreload 636 Watching for file changes with StatReloader
INFO 2021-06-14 00:46:13,043 autoreload 636 Watching for file changes with StatReloader
ERROR 2021-06-14 00:46:17,733 log 224 Internal Server Error: /user/641210592@qq.com/count/
Traceback (most recent call last):
  File "F:\Python\Python_Venv\Django_AutoTest\lib\site-packages\rest_framework\fields.py", line 457, in get_attribute
    return get_attribute(instance, self.source_attrs)
  File "F:\Python\Python_Venv\Django_AutoTest\lib\site-packages\rest_framework\fields.py", line 97, in get_attribute
    instance = getattr(instance, attr)
AttributeError: 'QuerySet' object has no attribute 'password'

During handling of the above exception, another exception occurred:

Traceback (most recent call last):
  File "F:\Python\Python_Venv\Django_AutoTest\lib\site-packages\django\core\handlers\exception.py", line 47, in inner
    response = get_response(request)
  File "F:\Python\Python_Venv\Django_AutoTest\lib\site-packages\django\core\handlers\base.py", line 181, in _get_response
    response = wrapped_callback(request, *callback_args, **callback_kwargs)
  File "F:\Python\Python_Venv\Django_AutoTest\lib\site-packages\django\views\decorators\csrf.py", line 54, in wrapped_view
    return view_func(*args, **kwargs)
  File "F:\Python\Python_Venv\Django_AutoTest\lib\site-packages\rest_framework\viewsets.py", line 125, in view
    return self.dispatch(request, *args, **kwargs)
  File "F:\Python\Python_Venv\Django_AutoTest\lib\site-packages\rest_framework\views.py", line 509, in dispatch
    response = self.handle_exception(exc)
  File "F:\Python\Python_Venv\Django_AutoTest\lib\site-packages\rest_framework\views.py", line 469, in handle_exception
    self.raise_uncaught_exception(exc)
  File "F:\Python\Python_Venv\Django_AutoTest\lib\site-packages\rest_framework\views.py", line 480, in raise_uncaught_exception
    raise exc
  File "F:\Python\Python_Venv\Django_AutoTest\lib\site-packages\rest_framework\views.py", line 506, in dispatch
    response = handler(request, *args, **kwargs)
  File "F:\Python\Python_Project\python_test_developer\users\views.py", line 68, in count_username_email
    response_data = serializer.data
  File "F:\Python\Python_Venv\Django_AutoTest\lib\site-packages\rest_framework\serializers.py", line 548, in data
    ret = super().data
  File "F:\Python\Python_Venv\Django_AutoTest\lib\site-packages\rest_framework\serializers.py", line 246, in data
    self._data = self.to_representation(self.instance)
  File "F:\Python\Python_Venv\Django_AutoTest\lib\site-packages\rest_framework\serializers.py", line 502, in to_representation
    attribute = field.get_attribute(instance)
  File "F:\Python\Python_Venv\Django_AutoTest\lib\site-packages\rest_framework\fields.py", line 490, in get_attribute
    raise type(exc)(msg)
AttributeError: Got AttributeError when attempting to get a value for field `password` on serializer `UserCountSeralizer`.
The serializer field might be named incorrectly and not match any attribute or key on the `QuerySet` instance.
Original exception text was: 'QuerySet' object has no attribute 'password'.
ERROR 2021-06-14 00:46:17,744 basehttp 161 "GET /user/641210592@qq.com/count/ HTTP/1.1" 500 132651
INFO 2021-06-14 00:47:06,409 autoreload 250 F:\Python\Python_Project\python_test_developer\users\serializers.py changed, reloading.
INFO 2021-06-14 00:47:08,690 autoreload 636 Watching for file changes with StatReloader
ERROR 2021-06-14 00:47:16,343 log 224 Internal Server Error: /user/641210592@qq.com/count/
Traceback (most recent call last):
  File "F:\Python\Python_Venv\Django_AutoTest\lib\site-packages\rest_framework\fields.py", line 457, in get_attribute
    return get_attribute(instance, self.source_attrs)
  File "F:\Python\Python_Venv\Django_AutoTest\lib\site-packages\rest_framework\fields.py", line 97, in get_attribute
    instance = getattr(instance, attr)
AttributeError: 'QuerySet' object has no attribute 'password'

During handling of the above exception, another exception occurred:

Traceback (most recent call last):
  File "F:\Python\Python_Venv\Django_AutoTest\lib\site-packages\django\core\handlers\exception.py", line 47, in inner
    response = get_response(request)
  File "F:\Python\Python_Venv\Django_AutoTest\lib\site-packages\django\core\handlers\base.py", line 181, in _get_response
    response = wrapped_callback(request, *callback_args, **callback_kwargs)
  File "F:\Python\Python_Venv\Django_AutoTest\lib\site-packages\django\views\decorators\csrf.py", line 54, in wrapped_view
    return view_func(*args, **kwargs)
  File "F:\Python\Python_Venv\Django_AutoTest\lib\site-packages\rest_framework\viewsets.py", line 125, in view
    return self.dispatch(request, *args, **kwargs)
  File "F:\Python\Python_Venv\Django_AutoTest\lib\site-packages\rest_framework\views.py", line 509, in dispatch
    response = self.handle_exception(exc)
  File "F:\Python\Python_Venv\Django_AutoTest\lib\site-packages\rest_framework\views.py", line 469, in handle_exception
    self.raise_uncaught_exception(exc)
  File "F:\Python\Python_Venv\Django_AutoTest\lib\site-packages\rest_framework\views.py", line 480, in raise_uncaught_exception
    raise exc
  File "F:\Python\Python_Venv\Django_AutoTest\lib\site-packages\rest_framework\views.py", line 506, in dispatch
    response = handler(request, *args, **kwargs)
  File "F:\Python\Python_Project\python_test_developer\users\views.py", line 68, in count_username_email
    response_data = serializer.data
  File "F:\Python\Python_Venv\Django_AutoTest\lib\site-packages\rest_framework\serializers.py", line 548, in data
    ret = super().data
  File "F:\Python\Python_Venv\Django_AutoTest\lib\site-packages\rest_framework\serializers.py", line 246, in data
    self._data = self.to_representation(self.instance)
  File "F:\Python\Python_Venv\Django_AutoTest\lib\site-packages\rest_framework\serializers.py", line 502, in to_representation
    attribute = field.get_attribute(instance)
  File "F:\Python\Python_Venv\Django_AutoTest\lib\site-packages\rest_framework\fields.py", line 490, in get_attribute
    raise type(exc)(msg)
AttributeError: Got AttributeError when attempting to get a value for field `password` on serializer `UserCountSeralizer`.
The serializer field might be named incorrectly and not match any attribute or key on the `QuerySet` instance.
Original exception text was: 'QuerySet' object has no attribute 'password'.
ERROR 2021-06-14 00:47:16,356 basehttp 161 "GET /user/641210592@qq.com/count/ HTTP/1.1" 500 133343
INFO 2021-06-14 00:47:21,730 autoreload 250 F:\Python\Python_Project\python_test_developer\users\serializers.py changed, reloading.
INFO 2021-06-14 00:47:24,097 autoreload 636 Watching for file changes with StatReloader
INFO 2021-06-14 00:48:07,139 autoreload 250 F:\Python\Python_Project\python_test_developer\users\serializers.py changed, reloading.
INFO 2021-06-14 00:48:09,289 autoreload 636 Watching for file changes with StatReloader
INFO 2021-06-14 00:48:17,855 autoreload 636 Watching for file changes with StatReloader
INFO 2021-06-14 00:49:10,861 autoreload 250 F:\Python\Python_Project\python_test_developer\users\views.py changed, reloading.
INFO 2021-06-14 00:49:21,309 autoreload 636 Watching for file changes with StatReloader
ERROR 2021-06-14 00:49:26,281 log 224 Internal Server Error: /user/641210592@qq.com/count/
Traceback (most recent call last):
  File "F:\Python\Python_Venv\Django_AutoTest\lib\site-packages\django\core\handlers\exception.py", line 47, in inner
    response = get_response(request)
  File "F:\Python\Python_Venv\Django_AutoTest\lib\site-packages\django\core\handlers\base.py", line 181, in _get_response
    response = wrapped_callback(request, *callback_args, **callback_kwargs)
  File "F:\Python\Python_Venv\Django_AutoTest\lib\site-packages\django\views\decorators\csrf.py", line 54, in wrapped_view
    return view_func(*args, **kwargs)
  File "F:\Python\Python_Venv\Django_AutoTest\lib\site-packages\rest_framework\viewsets.py", line 125, in view
    return self.dispatch(request, *args, **kwargs)
  File "F:\Python\Python_Venv\Django_AutoTest\lib\site-packages\rest_framework\views.py", line 509, in dispatch
    response = self.handle_exception(exc)
  File "F:\Python\Python_Venv\Django_AutoTest\lib\site-packages\rest_framework\views.py", line 469, in handle_exception
    self.raise_uncaught_exception(exc)
  File "F:\Python\Python_Venv\Django_AutoTest\lib\site-packages\rest_framework\views.py", line 480, in raise_uncaught_exception
    raise exc
  File "F:\Python\Python_Venv\Django_AutoTest\lib\site-packages\rest_framework\views.py", line 506, in dispatch
    response = handler(request, *args, **kwargs)
  File "F:\Python\Python_Project\python_test_developer\users\views.py", line 68, in count_username_email
    serializer.is_valid(raise_exception=True)
  File "F:\Python\Python_Venv\Django_AutoTest\lib\site-packages\rest_framework\serializers.py", line 213, in is_valid
    assert hasattr(self, 'initial_data'), (
AssertionError: Cannot call `.is_valid()` as no `data=` keyword argument was passed when instantiating the serializer instance.
ERROR 2021-06-14 00:49:26,289 basehttp 161 "GET /user/641210592@qq.com/count/ HTTP/1.1" 500 103949
INFO 2021-06-14 00:49:34,061 autoreload 250 F:\Python\Python_Project\python_test_developer\users\views.py changed, reloading.
INFO 2021-06-14 00:49:36,513 autoreload 636 Watching for file changes with StatReloader
WARNING 2021-06-14 00:49:38,650 log 224 Bad Request: /user/641210592@qq.com/count/
WARNING 2021-06-14 00:49:38,652 basehttp 161 "GET /user/641210592@qq.com/count/ HTTP/1.1" 400 89
INFO 2021-06-14 00:56:00,426 autoreload 636 Watching for file changes with StatReloader
INFO 2021-06-14 00:56:57,135 autoreload 636 Watching for file changes with StatReloader
ERROR 2021-06-14 00:56:59,866 log 224 Internal Server Error: /user/641210592@qq.com/count/
Traceback (most recent call last):
  File "F:\Python\Python_Venv\Django_AutoTest\lib\site-packages\rest_framework\fields.py", line 457, in get_attribute
    return get_attribute(instance, self.source_attrs)
  File "F:\Python\Python_Venv\Django_AutoTest\lib\site-packages\rest_framework\fields.py", line 97, in get_attribute
    instance = getattr(instance, attr)
AttributeError: 'QuerySet' object has no attribute 'id'

During handling of the above exception, another exception occurred:

Traceback (most recent call last):
  File "F:\Python\Python_Venv\Django_AutoTest\lib\site-packages\django\core\handlers\exception.py", line 47, in inner
    response = get_response(request)
  File "F:\Python\Python_Venv\Django_AutoTest\lib\site-packages\django\core\handlers\base.py", line 181, in _get_response
    response = wrapped_callback(request, *callback_args, **callback_kwargs)
  File "F:\Python\Python_Venv\Django_AutoTest\lib\site-packages\django\views\decorators\csrf.py", line 54, in wrapped_view
    return view_func(*args, **kwargs)
  File "F:\Python\Python_Venv\Django_AutoTest\lib\site-packages\rest_framework\viewsets.py", line 125, in view
    return self.dispatch(request, *args, **kwargs)
  File "F:\Python\Python_Venv\Django_AutoTest\lib\site-packages\rest_framework\views.py", line 509, in dispatch
    response = self.handle_exception(exc)
  File "F:\Python\Python_Venv\Django_AutoTest\lib\site-packages\rest_framework\views.py", line 469, in handle_exception
    self.raise_uncaught_exception(exc)
  File "F:\Python\Python_Venv\Django_AutoTest\lib\site-packages\rest_framework\views.py", line 480, in raise_uncaught_exception
    raise exc
  File "F:\Python\Python_Venv\Django_AutoTest\lib\site-packages\rest_framework\views.py", line 506, in dispatch
    response = handler(request, *args, **kwargs)
  File "F:\Python\Python_Project\python_test_developer\users\views.py", line 68, in count_username_email
    response_data = serializer.data
  File "F:\Python\Python_Venv\Django_AutoTest\lib\site-packages\rest_framework\serializers.py", line 548, in data
    ret = super().data
  File "F:\Python\Python_Venv\Django_AutoTest\lib\site-packages\rest_framework\serializers.py", line 246, in data
    self._data = self.to_representation(self.instance)
  File "F:\Python\Python_Venv\Django_AutoTest\lib\site-packages\rest_framework\serializers.py", line 502, in to_representation
    attribute = field.get_attribute(instance)
  File "F:\Python\Python_Venv\Django_AutoTest\lib\site-packages\rest_framework\fields.py", line 490, in get_attribute
    raise type(exc)(msg)
AttributeError: Got AttributeError when attempting to get a value for field `id` on serializer `UserCountSeralizer`.
The serializer field might be named incorrectly and not match any attribute or key on the `QuerySet` instance.
Original exception text was: 'QuerySet' object has no attribute 'id'.
ERROR 2021-06-14 00:56:59,877 basehttp 161 "GET /user/641210592@qq.com/count/ HTTP/1.1" 500 125941
INFO 2021-06-14 00:58:57,577 autoreload 636 Watching for file changes with StatReloader
ERROR 2021-06-14 00:59:06,861 log 224 Internal Server Error: /user/641210592@qq.com/count/
Traceback (most recent call last):
  File "F:\Python\Python_Venv\Django_AutoTest\lib\site-packages\django\core\handlers\exception.py", line 47, in inner
    response = get_response(request)
  File "F:\Python\Python_Venv\Django_AutoTest\lib\site-packages\django\core\handlers\base.py", line 181, in _get_response
    response = wrapped_callback(request, *callback_args, **callback_kwargs)
  File "F:\Python\Python_Venv\Django_AutoTest\lib\site-packages\django\views\decorators\csrf.py", line 54, in wrapped_view
    return view_func(*args, **kwargs)
  File "F:\Python\Python_Venv\Django_AutoTest\lib\site-packages\rest_framework\viewsets.py", line 125, in view
    return self.dispatch(request, *args, **kwargs)
  File "F:\Python\Python_Venv\Django_AutoTest\lib\site-packages\rest_framework\views.py", line 509, in dispatch
    response = self.handle_exception(exc)
  File "F:\Python\Python_Venv\Django_AutoTest\lib\site-packages\rest_framework\views.py", line 469, in handle_exception
    self.raise_uncaught_exception(exc)
  File "F:\Python\Python_Venv\Django_AutoTest\lib\site-packages\rest_framework\views.py", line 480, in raise_uncaught_exception
    raise exc
  File "F:\Python\Python_Venv\Django_AutoTest\lib\site-packages\rest_framework\views.py", line 506, in dispatch
    response = handler(request, *args, **kwargs)
  File "F:\Python\Python_Project\python_test_developer\users\views.py", line 69, in count_username_email
    response_data["count"] = queryset.count()
TypeError: list indices must be integers or slices, not str
ERROR 2021-06-14 00:59:06,872 basehttp 161 "GET /user/641210592@qq.com/count/ HTTP/1.1" 500 99557
INFO 2021-06-14 00:59:36,981 autoreload 250 F:\Python\Python_Project\python_test_developer\users\views.py changed, reloading.
INFO 2021-06-14 00:59:53,637 autoreload 636 Watching for file changes with StatReloader
ERROR 2021-06-14 01:00:00,382 log 224 Internal Server Error: /user/641210592@qq.com/count/
Traceback (most recent call last):
  File "F:\Python\Python_Venv\Django_AutoTest\lib\site-packages\django\core\handlers\exception.py", line 47, in inner
    response = get_response(request)
  File "F:\Python\Python_Venv\Django_AutoTest\lib\site-packages\django\core\handlers\base.py", line 181, in _get_response
    response = wrapped_callback(request, *callback_args, **callback_kwargs)
  File "F:\Python\Python_Venv\Django_AutoTest\lib\site-packages\django\views\decorators\csrf.py", line 54, in wrapped_view
    return view_func(*args, **kwargs)
  File "F:\Python\Python_Venv\Django_AutoTest\lib\site-packages\rest_framework\viewsets.py", line 125, in view
    return self.dispatch(request, *args, **kwargs)
  File "F:\Python\Python_Venv\Django_AutoTest\lib\site-packages\rest_framework\views.py", line 509, in dispatch
    response = self.handle_exception(exc)
  File "F:\Python\Python_Venv\Django_AutoTest\lib\site-packages\rest_framework\views.py", line 469, in handle_exception
    self.raise_uncaught_exception(exc)
  File "F:\Python\Python_Venv\Django_AutoTest\lib\site-packages\rest_framework\views.py", line 480, in raise_uncaught_exception
    raise exc
  File "F:\Python\Python_Venv\Django_AutoTest\lib\site-packages\rest_framework\views.py", line 506, in dispatch
    response = handler(request, *args, **kwargs)
  File "F:\Python\Python_Project\python_test_developer\users\views.py", line 69, in count_username_email
    response_data["count"] = queryset.count()
AttributeError: 'User' object has no attribute 'count'
ERROR 2021-06-14 01:00:00,394 basehttp 161 "GET /user/641210592@qq.com/count/ HTTP/1.1" 500 99538
INFO 2021-06-14 01:00:16,808 autoreload 250 F:\Python\Python_Project\python_test_developer\users\views.py changed, reloading.
INFO 2021-06-14 01:00:19,245 autoreload 636 Watching for file changes with StatReloader
INFO 2021-06-14 01:00:22,062 autoreload 250 F:\Python\Python_Project\python_test_developer\users\views.py changed, reloading.
INFO 2021-06-14 01:00:24,460 autoreload 636 Watching for file changes with StatReloader
INFO 2021-06-14 01:00:28,317 autoreload 250 F:\Python\Python_Project\python_test_developer\users\views.py changed, reloading.
INFO 2021-06-14 01:00:30,546 autoreload 636 Watching for file changes with StatReloader
ERROR 2021-06-14 01:00:58,087 log 224 Internal Server Error: /user/641210592@qq.com/count/
Traceback (most recent call last):
  File "F:\Python\Python_Venv\Django_AutoTest\lib\site-packages\django\core\handlers\exception.py", line 47, in inner
    response = get_response(request)
  File "F:\Python\Python_Venv\Django_AutoTest\lib\site-packages\django\core\handlers\base.py", line 181, in _get_response
    response = wrapped_callback(request, *callback_args, **callback_kwargs)
  File "F:\Python\Python_Venv\Django_AutoTest\lib\site-packages\django\views\decorators\csrf.py", line 54, in wrapped_view
    return view_func(*args, **kwargs)
  File "F:\Python\Python_Venv\Django_AutoTest\lib\site-packages\rest_framework\viewsets.py", line 125, in view
    return self.dispatch(request, *args, **kwargs)
  File "F:\Python\Python_Venv\Django_AutoTest\lib\site-packages\rest_framework\views.py", line 509, in dispatch
    response = self.handle_exception(exc)
  File "F:\Python\Python_Venv\Django_AutoTest\lib\site-packages\rest_framework\views.py", line 469, in handle_exception
    self.raise_uncaught_exception(exc)
  File "F:\Python\Python_Venv\Django_AutoTest\lib\site-packages\rest_framework\views.py", line 480, in raise_uncaught_exception
    raise exc
  File "F:\Python\Python_Venv\Django_AutoTest\lib\site-packages\rest_framework\views.py", line 506, in dispatch
    response = handler(request, *args, **kwargs)
  File "F:\Python\Python_Project\python_test_developer\users\views.py", line 67, in count_username_email
    serializer = self.get_serializer_class(instance=queryset)
TypeError: get_serializer_class() got an unexpected keyword argument 'instance'
ERROR 2021-06-14 01:00:58,101 basehttp 161 "GET /user/641210592@qq.com/count/ HTTP/1.1" 500 98889
INFO 2021-06-14 01:02:47,248 autoreload 250 F:\Python\Python_Project\python_test_developer\users\views.py changed, reloading.
INFO 2021-06-14 01:02:49,523 autoreload 636 Watching for file changes with StatReloader
ERROR 2021-06-14 01:03:00,256 log 224 Internal Server Error: /user/641210592@qq.com/count/
Traceback (most recent call last):
  File "F:\Python\Python_Venv\Django_AutoTest\lib\site-packages\django\core\handlers\exception.py", line 47, in inner
    response = get_response(request)
  File "F:\Python\Python_Venv\Django_AutoTest\lib\site-packages\django\core\handlers\base.py", line 181, in _get_response
    response = wrapped_callback(request, *callback_args, **callback_kwargs)
  File "F:\Python\Python_Venv\Django_AutoTest\lib\site-packages\django\views\decorators\csrf.py", line 54, in wrapped_view
    return view_func(*args, **kwargs)
  File "F:\Python\Python_Venv\Django_AutoTest\lib\site-packages\rest_framework\viewsets.py", line 125, in view
    return self.dispatch(request, *args, **kwargs)
  File "F:\Python\Python_Venv\Django_AutoTest\lib\site-packages\rest_framework\views.py", line 509, in dispatch
    response = self.handle_exception(exc)
  File "F:\Python\Python_Venv\Django_AutoTest\lib\site-packages\rest_framework\views.py", line 469, in handle_exception
    self.raise_uncaught_exception(exc)
  File "F:\Python\Python_Venv\Django_AutoTest\lib\site-packages\rest_framework\views.py", line 480, in raise_uncaught_exception
    raise exc
  File "F:\Python\Python_Venv\Django_AutoTest\lib\site-packages\rest_framework\views.py", line 506, in dispatch
    response = handler(request, *args, **kwargs)
  File "F:\Python\Python_Project\python_test_developer\users\views.py", line 69, in count_username_email
    response_data["count"] = queryset.count()
AttributeError: 'User' object has no attribute 'count'
ERROR 2021-06-14 01:03:00,269 basehttp 161 "GET /user/641210592@qq.com/count/ HTTP/1.1" 500 99910
ERROR 2021-06-14 01:03:34,370 log 224 Internal Server Error: /user/641210592@qq.com/count/
Traceback (most recent call last):
  File "F:\Python\Python_Venv\Django_AutoTest\lib\site-packages\django\core\handlers\exception.py", line 47, in inner
    response = get_response(request)
  File "F:\Python\Python_Venv\Django_AutoTest\lib\site-packages\django\core\handlers\base.py", line 181, in _get_response
    response = wrapped_callback(request, *callback_args, **callback_kwargs)
  File "F:\Python\Python_Venv\Django_AutoTest\lib\site-packages\django\views\decorators\csrf.py", line 54, in wrapped_view
    return view_func(*args, **kwargs)
  File "F:\Python\Python_Venv\Django_AutoTest\lib\site-packages\rest_framework\viewsets.py", line 125, in view
    return self.dispatch(request, *args, **kwargs)
  File "F:\Python\Python_Venv\Django_AutoTest\lib\site-packages\rest_framework\views.py", line 509, in dispatch
    response = self.handle_exception(exc)
  File "F:\Python\Python_Venv\Django_AutoTest\lib\site-packages\rest_framework\views.py", line 469, in handle_exception
    self.raise_uncaught_exception(exc)
  File "F:\Python\Python_Venv\Django_AutoTest\lib\site-packages\rest_framework\views.py", line 480, in raise_uncaught_exception
    raise exc
  File "F:\Python\Python_Venv\Django_AutoTest\lib\site-packages\rest_framework\views.py", line 506, in dispatch
    response = handler(request, *args, **kwargs)
  File "F:\Python\Python_Project\python_test_developer\users\views.py", line 69, in count_username_email
    response_data["count"] = queryset.count()
AttributeError: 'User' object has no attribute 'count'
ERROR 2021-06-14 01:03:34,379 basehttp 161 "GET /user/641210592@qq.com/count/ HTTP/1.1" 500 100199
INFO 2021-06-14 01:04:13,472 autoreload 250 F:\Python\Python_Project\python_test_developer\users\views.py changed, reloading.
INFO 2021-06-14 01:04:15,747 autoreload 636 Watching for file changes with StatReloader
INFO 2021-06-14 01:04:59,950 autoreload 250 F:\Python\Python_Project\python_test_developer\users\views.py changed, reloading.
INFO 2021-06-14 01:05:02,171 autoreload 636 Watching for file changes with StatReloader
INFO 2021-06-14 01:05:15,616 basehttp 161 "GET /user/641210592@qq.com/count/ HTTP/1.1" 200 66
INFO 2021-06-14 01:05:27,140 autoreload 636 Watching for file changes with StatReloader
INFO 2021-06-14 01:05:33,197 basehttp 161 "GET /user/sunwang/count/ HTTP/1.1" 200 66
INFO 2021-06-14 01:05:38,985 autoreload 250 F:\Python\Python_Project\python_test_developer\users\views.py changed, reloading.
INFO 2021-06-14 01:09:55,767 autoreload 636 Watching for file changes with StatReloader
INFO 2021-06-14 01:09:58,254 basehttp 161 "GET /user/sunwang/count/ HTTP/1.1" 200 70
INFO 2021-06-14 01:10:19,692 autoreload 250 F:\Python\Python_Project\python_test_developer\users\views.py changed, reloading.
INFO 2021-06-14 01:10:21,905 autoreload 636 Watching for file changes with StatReloader
INFO 2021-06-14 01:10:49,782 autoreload 636 Watching for file changes with StatReloader
INFO 2021-06-14 01:10:52,099 basehttp 161 "GET /user/sunwang/count/ HTTP/1.1" 200 68
INFO 2021-06-14 01:11:28,873 basehttp 161 "GET /user/sunwan/count/ HTTP/1.1" 200 11
INFO 2021-06-14 01:11:39,486 basehttp 161 "GET /user/sunwang/count/ HTTP/1.1" 200 68
INFO 2021-06-14 01:11:43,144 autoreload 250 F:\Python\Python_Project\python_test_developer\users\views.py changed, reloading.
INFO 2021-06-14 01:11:45,322 autoreload 636 Watching for file changes with StatReloader
INFO 2021-06-14 07:44:22,413 autoreload 636 Watching for file changes with StatReloader
INFO 2021-06-14 07:44:29,163 basehttp 161 "GET /user/sunwang/count/ HTTP/1.1" 200 0
INFO 2021-06-14 07:45:24,241 autoreload 636 Watching for file changes with StatReloader
INFO 2021-06-14 07:45:31,584 basehttp 161 "GET /user/sunwang/count/ HTTP/1.1" 200 66
INFO 2021-06-14 07:49:34,704 autoreload 636 Watching for file changes with StatReloader
INFO 2021-06-14 07:50:13,412 basehttp 161 "GET /user/sunwang/count/ HTTP/1.1" 200 0
INFO 2021-06-14 07:50:41,687 autoreload 250 F:\Python\Python_Project\python_test_developer\users\views.py changed, reloading.
INFO 2021-06-14 07:50:49,656 basehttp 161 "GET /user/sunwang/count/ HTTP/1.1" 200 0
INFO 2021-06-14 07:50:52,124 autoreload 636 Watching for file changes with StatReloader
INFO 2021-06-14 07:50:58,963 basehttp 161 "GET /user/sunwang/count/ HTTP/1.1" 200 32
INFO 2021-06-14 07:51:11,607 autoreload 250 F:\Python\Python_Project\python_test_developer\users\views.py changed, reloading.
INFO 2021-06-14 07:51:14,195 autoreload 636 Watching for file changes with StatReloader
INFO 2021-06-14 07:54:49,713 autoreload 636 Watching for file changes with StatReloader
INFO 2021-06-14 07:54:52,375 basehttp 161 "GET /user/sunwang/count/ HTTP/1.1" 200 32
INFO 2021-06-14 07:55:20,699 autoreload 250 F:\Python\Python_Project\python_test_developer\users\serializers.py changed, reloading.
